Workbook
Name bulan: Data!$B$9:$B$20
Name sumber_dana: Data!$U$1:$U$2

Sheet Data
U1: SILPA REGULER
A2: DATA SEKOLAH | U2: BOS REGULER
A3: NPSN | C3: 20205293
A4: SEKOLAH | C4: SD NEGERI PASIRHALANG
A5: KECAMATAN | C5: CIKALONGWETAN
E6: =E9*2 -> 165120000 | G6: =E9+203400 -> 82763400 | H6: =G6-J13 -> 74722000
A7: DATA SALDO BOS REGULER
A8: No | B8: Bulan | C8: Tanggal Penutupan Bulan lalu | D8: Tanggal Penutupan Bulan berjalan | E8: Jumlah Penerimaan | F8: Jumlah Pengeluaran | G8: Saldo Bank | H8: Saldo Kas | I8: Saldo Pajak | J8: Jumlah Saldo Kas | K8: Nama Kepsek | L8: NIP Kepsek | M8: No. SK & Tanggal KS | N8: Nama Bendahara | O8: NIP | P8: No. SK & Tanggal Bendahara | Q8: Berita Acara
A9: 1 | B9: JANUARI | C9: 46022 | D9: 46053 | E9: 82560000 | F9: =E9-J9 -> 0 | G9: 82560000 | H9: 0 | I9: 0 | J9: =SUM(G9:I9) -> 82560000 | K9: YUNIARTI, S.Pd | L9: 196607071986102005 | M9: 800.1.13.3/062-BKPSDM tanggal 2 Januari 2026 | N9: AHMAD, S.Pd. | O9: 196805251992121003 | P9: 100.3.3.2/Kep. - BKAD/2026 | Q9: Pada hari ini Sabtu tanggal tiga puluh satu bulan Januari tahun Dua ribu dua puluh enam. Yang bertanda tangan di bawah ini, kami Kepala Sekolah yang ditunjuk berdasarkan Surat Keputusan Nomor : | S9: =TEXT(D9,"Dddd") -> Saturday
A10: 2 | B10: FEBRUARI | C10: =D9 -> 46053 | D10: 46081 | E10: 82560000 | F10: =E10-J10 -> 36375900 | G10: 37109100 | H10: 9075000 | I10: 0 | J10: =SUM(G10:I10) -> 46184100 | K10: =K9 -> YUNIARTI, S.Pd | L10: =L9 -> 196607071986102005 | M10: =M9 -> 800.1.13.3/062-BKPSDM tanggal 2 Januari 2026 | N10: =N9 -> AHMAD, S.Pd. | O10: =O9 -> 196805251992121003 | P10: =P9 -> 100.3.3.2/Kep. - BKAD/2026 | Q10: Pada hari ini Sabtu tanggal dua puluh delapan bulan Februari tahun Dua ribu dua puluh enam. Yang bertanda tangan di bawah ini, kami Kepala Sekolah yang ditunjuk berdasarkan Surat Keputusan Nomor : | S10: =TEXT(D10,"Dddd") -> Saturday
A11: 3 | B11: MARET | C11: =D10 -> 46081 | D11: 46112 | E11: 46184100 | F11: =E11-J11 -> 5300000 | G11: 37109100 | H11: 3775000 | I11: 0 | J11: =SUM(G11:I11) -> 40884100 | K11: =K10 -> YUNIARTI, S.Pd | L11: =L10 -> 196607071986102005 | M11: =M10 -> 800.1.13.3/062-BKPSDM tanggal 2 Januari 2026 | N11: =N10 -> AHMAD, S.Pd. | O11: =O10 -> 196805251992121003 | P11: =P10 -> 100.3.3.2/Kep. - BKAD/2026 | Q11: Pada hari ini Selasa tanggal tiga puluh satu bulan Maret tahun Dua ribu dua puluh enam. Yang bertanda tangan di bawah ini, kami Kepala Sekolah yang ditunjuk berdasarkan Surat Keputusan Nomor : | S11: =TEXT(D11,"Dddd") -> Tuesday
A12: 4 | B12: APRIL | C12: =D11 -> 46112 | D12: 46142 | E12: =J11 -> 40884100 | F12: =E12-J12 -> 31742700 | G12: 8041400 | H12: 1100000 | I12: 0 | J12: =SUM(G12:I12) -> 9141400 | K12: =K11 -> YUNIARTI, S.Pd | L12: =L11 -> 196607071986102005 | M12: =M11 -> 800.1.13.3/062-BKPSDM tanggal 2 Januari 2026 | N12: =N11 -> AHMAD, S.Pd. | O12: =O11 -> 196805251992121003 | P12: =P11 -> 100.3.3.2/Kep. - BKAD/2026 | Q12: Pada hari ini Kamis tanggal tiga puluh bulan April tahun Dua ribu dua puluh enam. Yang bertanda tangan di bawah ini, kami Kepala Sekolah yang ditunjuk berdasarkan Surat Keputusan Nomor : | S12: =TEXT(D12,"Dddd") -> Thursday
A13: 5 | B13: MEI | C13: =D12 -> 46142 | D13: 46172 | E13: =J12 -> 9141400 | F13: =E13-J13 -> 1100000 | G13: 8041400 | H13: 0 | I13: 0 | J13: =SUM(G13:I13) -> 8041400 | K13: =K12 -> YUNIARTI, S.Pd | L13: =L12 -> 196607071986102005 | M13: =M12 -> 800.1.13.3/062-BKPSDM tanggal 2 Januari 2026 | N13: =N12 -> AHMAD, S.Pd. | O13: =O12 -> 196805251992121003 | P13: =P12 -> 100.3.3.2/Kep. - BKAD/2026 | Q13: Pada hari ini Sabtu tanggal tiga puluh satu bulan Mei tahun Dua ribu dua puluh enam. Yang bertanda tangan di bawah ini, kami Kepala Sekolah yang ditunjuk berdasarkan Surat Keputusan Nomor : | S13: =TEXT(D13,"Dddd") -> Saturday
A14: 6 | B14: JUNI | C14: =D13 -> 46172 | D14: 46203 | E14: =J13 -> 8041400 | F14: =E14-J14 -> 8041400 | G14: 0 | H14: 0 | I14: 0 | J14: =SUM(G14:I14) -> 0 | K14: =K13 -> YUNIARTI, S.Pd | L14: =L13 -> 196607071986102005 | M14: =M13 -> 800.1.13.3/062-BKPSDM tanggal 2 Januari 2026 | N14: =N13 -> AHMAD, S.Pd. | O14: =O13 -> 196805251992121003 | P14: =P13 -> 100.3.3.2/Kep. - BKAD/2026 | Q14: Pada hari ini Selasa tanggal tiga puluh bulan Juni tahun Dua ribu dua puluh enam. Yang bertanda tangan di bawah ini, kami Kepala Sekolah yang ditunjuk berdasarkan Surat Keputusan Nomor : | S14: =TEXT(D14,"Dddd") -> Tuesday
A15: 7 | B15: JULI | C15: =D14 -> 46203 | D15: 45868 | F15: =E15-J15 -> 0 | I15: 0 | J15: =SUM(G15:I15) -> 0 | K15: =K14 -> YUNIARTI, S.Pd | L15: =L14 -> 196607071986102005 | M15: =M14 -> 800.1.13.3/062-BKPSDM tanggal 2 Januari 2026 | N15: =N14 -> AHMAD, S.Pd. | O15: =O14 -> 196805251992121003 | P15: =P14 -> 100.3.3.2/Kep. - BKAD/2026 | Q15: Pada hari ini Kamis tanggal tiga puluh satu bulan Juli tahun Dua ribu dua puluh enam. Yang bertanda tangan di bawah ini, kami Kepala Sekolah yang ditunjuk berdasarkan Surat Keputusan Nomor : | S15: =TEXT(D15,"Dddd") -> Wednesday
A16: 8 | B16: AGUSTUS | C16: =D15 -> 45868 | D16: 45900 | F16: =E16-J16 -> 0 | I16: 0 | J16: =SUM(G16:I16) -> 0 | K16: =K15 -> YUNIARTI, S.Pd | L16: =L15 -> 196607071986102005 | M16: =M15 -> 800.1.13.3/062-BKPSDM tanggal 2 Januari 2026 | N16: =N15 -> AHMAD, S.Pd. | O16: =O15 -> 196805251992121003 | P16: =P15 -> 100.3.3.2/Kep. - BKAD/2026 | Q16: Pada hari ini Senin tanggal tiga puluh satu bulan Agustus tahun Dua ribu dua puluh enam. Yang bertanda tangan di bawah ini, kami Kepala Sekolah yang ditunjuk berdasarkan Surat Keputusan Nomor : | S16: =TEXT(D16,"Dddd") -> Sunday
A17: 9 | B17: SEPTEMBER | C17: =D16 -> 45900 | D17: 45930 | F17: =E17-J17 -> 0 | I17: 0 | J17: =SUM(G17:I17) -> 0 | K17: =K16 -> YUNIARTI, S.Pd | L17: =L16 -> 196607071986102005 | M17: =M16 -> 800.1.13.3/062-BKPSDM tanggal 2 Januari 2026 | N17: =N16 -> AHMAD, S.Pd. | O17: =O16 -> 196805251992121003 | P17: =P16 -> 100.3.3.2/Kep. - BKAD/2026 | Q17: Pada hari ini Selasa tanggal tiga puluh bulan September tahun Dua ribu dua puluh enam. Yang bertanda tangan di bawah ini, kami Kepala Sekolah yang ditunjuk berdasarkan Surat Keputusan Nomor : | S17: =TEXT(D17,"Dddd") -> Tuesday
A18: 10 | B18: OKTOBER | C18: =D17 -> 45930 | D18: 45961 | F18: =E18-J18 -> 0 | I18: 0 | J18: =SUM(G18:I18) -> 0 | K18: =K17 -> YUNIARTI, S.Pd | L18: =L17 -> 196607071986102005 | M18: =M17 -> 800.1.13.3/062-BKPSDM tanggal 2 Januari 2026 | N18: =N17 -> AHMAD, S.Pd. | O18: =O17 -> 196805251992121003 | P18: =P17 -> 100.3.3.2/Kep. - BKAD/2026 | Q18: Pada hari ini Jumat tanggal tiga puluh bulan Oktober tahun Dua ribu dua puluh enam. Yang bertanda tangan di bawah ini, kami Kepala Sekolah yang ditunjuk berdasarkan Surat Keputusan Nomor : | S18: =TEXT(D18,"Dddd") -> Friday
A19: 11 | B19: NOVEMBER | C19: =D18 -> 45961 | D19: 45990 | F19: =E19-J19 -> 0 | I19: 0 | J19: =SUM(G19:I19) -> 0 | K19: =K18 -> YUNIARTI, S.Pd | L19: =L18 -> 196607071986102005 | M19: =M18 -> 800.1.13.3/062-BKPSDM tanggal 2 Januari 2026 | N19: =N18 -> AHMAD, S.Pd. | O19: =O18 -> 196805251992121003 | P19: =P18 -> 100.3.3.2/Kep. - BKAD/2026 | Q19: Pada hari ini Sabtu tanggal dua puluh sembilan bulan November tahun Dua ribu dua puluh enam. Yang bertanda tangan di bawah ini, kami Kepala Sekolah yang ditunjuk berdasarkan Surat Keputusan Nomor : | S19: =TEXT(D19,"Dddd") -> Saturday
A20: 12 | B20: DESEMBER | C20: =D19 -> 45990 | D20: 46022 | F20: =E20-J20 -> 0 | I20: 0 | J20: =SUM(G20:I20) -> 0 | K20: =K19 -> YUNIARTI, S.Pd | L20: =L19 -> 196607071986102005 | M20: =M19 -> 800.1.13.3/062-BKPSDM tanggal 2 Januari 2026 | N20: =N19 -> AHMAD, S.Pd. | O20: =O19 -> 196805251992121003 | P20: =P19 -> 100.3.3.2/Kep. - BKAD/2026 | Q20: Pada hari ini Rabu tanggal tiga puluh satu bulan Desember tahun Dua ribu dua puluh enam. Yang bertanda tangan di bawah ini, kami Kepala Sekolah yang ditunjuk berdasarkan Surat Keputusan Nomor : | S20: =TEXT(D20,"Dddd") -> Wednesday
A22: DATA SALDO SILPA BOS REGULER
A23: No | B23: Bulan | C23: Tanggal Penutupan Bulan lalu | D23: Tanggal Penutupan Bulan berjalan | E23: Jumlah Penerimaan | F23: Jumlah Pengeluaran | G23: Saldo Bank | H23: Saldo Kas | I23: Saldo Pajak | J23: Jumlah Saldo Kas | K23: Nama Kepsek | L23: NIP Kepsek | M23: No. SK & Tanggal KS | N23: Nama Kepsek | O23: NIP Kepsek | P23: No. SK & Tanggal KS | Q23: Berita Acara
A24: 1 | B24: =B9 -> JANUARI | C24: =C9 -> 46022 | D24: =D9 -> 46053 | E24: 0 | F24: 0 | G24: 0 | H24: 0 | I24: 0 | J24: =SUM(G24:I24) -> 0 | K24: =K9 -> YUNIARTI, S.Pd | L24: =L9 -> 196607071986102005 | M24: =M9 -> 800.1.13.3/062-BKPSDM tanggal 2 Januari 2026 | N24: =N9 -> AHMAD, S.Pd. | O24: =O9 -> 196805251992121003 | P24: =P9 -> 100.3.3.2/Kep. - BKAD/2026 | Q24: =Q9 -> Pada hari ini Sabtu tanggal tiga puluh satu bulan Januari tahun Dua ribu dua puluh enam. Yang bertanda tangan di bawah ini, kami Kepala Sekolah yang ditunjuk berdasarkan Surat Keputusan Nomor :
A25: 2 | B25: =B10 -> FEBRUARI | C25: =C10 -> 46053 | D25: =D10 -> 46081 | E25: 0 | F25: 0 | G25: 0 | H25: 0 | I25: 0 | J25: =SUM(G25:I25) -> 0 | K25: =K10 -> YUNIARTI, S.Pd | L25: =L10 -> 196607071986102005 | M25: =M10 -> 800.1.13.3/062-BKPSDM tanggal 2 Januari 2026 | N25: =N10 -> AHMAD, S.Pd. | O25: =O10 -> 196805251992121003 | P25: =P10 -> 100.3.3.2/Kep. - BKAD/2026 | Q25: =Q10 -> Pada hari ini Sabtu tanggal dua puluh delapan bulan Februari tahun Dua ribu dua puluh enam. Yang bertanda tangan di bawah ini, kami Kepala Sekolah yang ditunjuk berdasarkan Surat Keputusan Nomor :
A26: 3 | B26: =B11 -> MARET | C26: =C11 -> 46081 | D26: =D11 -> 46112 | E26: 0 | F26: 0 | G26: 0 | H26: 0 | I26: 0 | J26: =SUM(G26:I26) -> 0 | K26: =K11 -> YUNIARTI, S.Pd | L26: =L11 -> 196607071986102005 | M26: =M11 -> 800.1.13.3/062-BKPSDM tanggal 2 Januari 2026 | N26: =N11 -> AHMAD, S.Pd. | O26: =O11 -> 196805251992121003 | P26: =P11 -> 100.3.3.2/Kep. - BKAD/2026 | Q26: =Q11 -> Pada hari ini Selasa tanggal tiga puluh satu bulan Maret tahun Dua ribu dua puluh enam. Yang bertanda tangan di bawah ini, kami Kepala Sekolah yang ditunjuk berdasarkan Surat Keputusan Nomor :
A27: 4 | B27: =B12 -> APRIL | C27: =C12 -> 46112 | D27: =D12 -> 46142 | E27: 0 | F27: 0 | G27: 0 | H27: 0 | I27: 0 | J27: =SUM(G27:I27) -> 0 | K27: =K12 -> YUNIARTI, S.Pd | L27: =L12 -> 196607071986102005 | M27: =M12 -> 800.1.13.3/062-BKPSDM tanggal 2 Januari 2026 | N27: =N12 -> AHMAD, S.Pd. | O27: =O12 -> 196805251992121003 | P27: =P12 -> 100.3.3.2/Kep. - BKAD/2026 | Q27: =Q12 -> Pada hari ini Kamis tanggal tiga puluh bulan April tahun Dua ribu dua puluh enam. Yang bertanda tangan di bawah ini, kami Kepala Sekolah yang ditunjuk berdasarkan Surat Keputusan Nomor :
A28: 5 | B28: =B13 -> MEI | C28: =C13 -> 46142 | D28: =D13 -> 46172 | E28: 0 | F28: 0 | G28: 0 | H28: 0 | I28: 0 | J28: =SUM(G28:I28) -> 0 | K28: =K13 -> YUNIARTI, S.Pd | L28: =L13 -> 196607071986102005 | M28: =M13 -> 800.1.13.3/062-BKPSDM tanggal 2 Januari 2026 | N28: =N13 -> AHMAD, S.Pd. | O28: =O13 -> 196805251992121003 | P28: =P13 -> 100.3.3.2/Kep. - BKAD/2026 | Q28: =Q13 -> Pada hari ini Sabtu tanggal tiga puluh satu bulan Mei tahun Dua ribu dua puluh enam. Yang bertanda tangan di bawah ini, kami Kepala Sekolah yang ditunjuk berdasarkan Surat Keputusan Nomor :
A29: 6 | B29: =B14 -> JUNI | C29: =C14 -> 46172 | D29: =D14 -> 46203 | E29: 0 | F29: 0 | G29: 0 | H29: 0 | I29: 0 | J29: =SUM(G29:I29) -> 0 | K29: =K14 -> YUNIARTI, S.Pd | L29: =L14 -> 196607071986102005 | M29: =M14 -> 800.1.13.3/062-BKPSDM tanggal 2 Januari 2026 | N29: =N14 -> AHMAD, S.Pd. | O29: =O14 -> 196805251992121003 | P29: =P14 -> 100.3.3.2/Kep. - BKAD/2026 | Q29: =Q14 -> Pada hari ini Selasa tanggal tiga puluh bulan Juni tahun Dua ribu dua puluh enam. Yang bertanda tangan di bawah ini, kami Kepala Sekolah yang ditunjuk berdasarkan Surat Keputusan Nomor :
A30: 7 | B30: =B15 -> JULI | C30: =C15 -> 46203 | D30: =D15 -> 45868 | E30: 0 | F30: 0 | G30: 0 | H30: 0 | I30: 0 | J30: =SUM(G30:I30) -> 0 | K30: =K15 -> YUNIARTI, S.Pd | L30: =L15 -> 196607071986102005 | M30: =M15 -> 800.1.13.3/062-BKPSDM tanggal 2 Januari 2026 | N30: =N15 -> AHMAD, S.Pd. | O30: =O15 -> 196805251992121003 | P30: =P15 -> 100.3.3.2/Kep. - BKAD/2026 | Q30: =Q15 -> Pada hari ini Kamis tanggal tiga puluh satu bulan Juli tahun Dua ribu dua puluh enam. Yang bertanda tangan di bawah ini, kami Kepala Sekolah yang ditunjuk berdasarkan Surat Keputusan Nomor :
A31: 8 | B31: =B16 -> AGUSTUS | C31: =C16 -> 45868 | D31: =D16 -> 45900 | E31: 0 | F31: 0 | G31: 0 | H31: 0 | I31: 0 | J31: =SUM(G31:I31) -> 0 | K31: =K16 -> YUNIARTI, S.Pd | L31: =L16 -> 196607071986102005 | M31: =M16 -> 800.1.13.3/062-BKPSDM tanggal 2 Januari 2026 | N31: =N16 -> AHMAD, S.Pd. | O31: =O16 -> 196805251992121003 | P31: =P16 -> 100.3.3.2/Kep. - BKAD/2026 | Q31: =Q16 -> Pada hari ini Senin tanggal tiga puluh satu bulan Agustus tahun Dua ribu dua puluh enam. Yang bertanda tangan di bawah ini, kami Kepala Sekolah yang ditunjuk berdasarkan Surat Keputusan Nomor :
A32: 9 | B32: =B17 -> SEPTEMBER | C32: =C17 -> 45900 | D32: =D17 -> 45930 | E32: 0 | F32: 0 | G32: 0 | H32: 0 | I32: 0 | J32: =SUM(G32:I32) -> 0 | K32: =K17 -> YUNIARTI, S.Pd | L32: =L17 -> 196607071986102005 | M32: =M17 -> 800.1.13.3/062-BKPSDM tanggal 2 Januari 2026 | N32: =N17 -> AHMAD, S.Pd. | O32: =O17 -> 196805251992121003 | P32: =P17 -> 100.3.3.2/Kep. - BKAD/2026 | Q32: =Q17 -> Pada hari ini Selasa tanggal tiga puluh bulan September tahun Dua ribu dua puluh enam. Yang bertanda tangan di bawah ini, kami Kepala Sekolah yang ditunjuk berdasarkan Surat Keputusan Nomor :
A33: 10 | B33: =B18 -> OKTOBER | C33: =C18 -> 45930 | D33: =D18 -> 45961 | E33: 0 | F33: 0 | G33: 0 | H33: 0 | I33: 0 | J33: =SUM(G33:I33) -> 0 | K33: =K18 -> YUNIARTI, S.Pd | L33: =L18 -> 196607071986102005 | M33: =M18 -> 800.1.13.3/062-BKPSDM tanggal 2 Januari 2026 | N33: =N18 -> AHMAD, S.Pd. | O33: =O18 -> 196805251992121003 | P33: =P18 -> 100.3.3.2/Kep. - BKAD/2026 | Q33: =Q18 -> Pada hari ini Jumat tanggal tiga puluh bulan Oktober tahun Dua ribu dua puluh enam. Yang bertanda tangan di bawah ini, kami Kepala Sekolah yang ditunjuk berdasarkan Surat Keputusan Nomor :
A34: 11 | B34: =B19 -> NOVEMBER | C34: =C19 -> 45961 | D34: =D19 -> 45990 | E34: 0 | F34: 0 | G34: 0 | H34: 0 | I34: 0 | J34: =SUM(G34:I34) -> 0 | K34: =K19 -> YUNIARTI, S.Pd | L34: =L19 -> 196607071986102005 | M34: =M19 -> 800.1.13.3/062-BKPSDM tanggal 2 Januari 2026 | N34: =N19 -> AHMAD, S.Pd. | O34: =O19 -> 196805251992121003 | P34: =P19 -> 100.3.3.2/Kep. - BKAD/2026 | Q34: =Q19 -> Pada hari ini Sabtu tanggal dua puluh sembilan bulan November tahun Dua ribu dua puluh enam. Yang bertanda tangan di bawah ini, kami Kepala Sekolah yang ditunjuk berdasarkan Surat Keputusan Nomor :
A35: 12 | B35: =B20 -> DESEMBER | C35: =C20 -> 45990 | D35: =D20 -> 46022 | E35: 0 | F35: 0 | G35: 0 | H35: 0 | I35: 0 | J35: =SUM(G35:I35) -> 0 | K35: =K20 -> YUNIARTI, S.Pd | L35: =L20 -> 196607071986102005 | M35: =M20 -> 800.1.13.3/062-BKPSDM tanggal 2 Januari 2026 | N35: =N20 -> AHMAD, S.Pd. | O35: =O20 -> 196805251992121003 | P35: =P20 -> 100.3.3.2/Kep. - BKAD/2026 | Q35: =Q20 -> Pada hari ini Rabu tanggal tiga puluh satu bulan Desember tahun Dua ribu dua puluh enam. Yang bertanda tangan di bawah ini, kami Kepala Sekolah yang ditunjuk berdasarkan Surat Keputusan Nomor :

Sheet Register Kas
B3: REGISTER PENUTUPAN KAS | J3: BOS REGULER
B4: =J3 -> BOS REGULER | J4: Pilih Bulan
B5: ="PERIODE : BULAN "&J5&" "&2026 -> PERIODE : BULAN JANUARI 2026 | J5: JANUARI
B7: Tanggal Penutupan Kas | E7: : | F7: =IF($J$3="","",IF($J$3="BOS REGULER",(VLOOKUP($J$5,Data!$B$9:$P$20,3,FALSE)),IF($J$3="SILPA REGULER",(VLOOKUP($J$5,Data!$B$24:$P$35,3,FALSE))))) -> 46053
B8: Nama Penutup Kas (Pemegang kas) | E8: : | F8: =IF($J$3="","",IF($J$3="BOS REGULER",(VLOOKUP($J$5,Data!$B$9:$P$20,13,FALSE)),IF($J$3="SILPA REGULER",(VLOOKUP($J$5,Data!$B$24:$P$35,13,FALSE))))) -> AHMAD, S.Pd.
B9: Tanggal penutupan Kas yang lalu | E9: : | F9: =IF($J$3="","",IF($J$3="BOS REGULER",(VLOOKUP($J$5,Data!$B$9:$P$20,2,FALSE)),IF($J$3="SILPA REGULER",(VLOOKUP($J$5,Data!$B$24:$P$35,2,FALSE))))) -> 46022
B10: Jumlah Total Penerimaan (D) | E10: : | F10: =IF($J$3="","",IF($J$3="BOS REGULER",(VLOOKUP($J$5,Data!$B$9:$P$20,4,FALSE)),IF($J$3="SILPA REGULER",(VLOOKUP($J$5,Data!$B$24:$P$35,4,FALSE))))) -> 82560000
B11: Jumlah Total Pengeluaran (K) | E11: : | F11: =IF($J$3="","",IF($J$3="BOS REGULER",(VLOOKUP($J$5,Data!$B$9:$P$20,5,FALSE)),IF($J$3="SILPA REGULER",(VLOOKUP($J$5,Data!$B$24:$P$35,5,FALSE))))) -> 0
B12: Saldo Buku (A = D - K) | E12: : | F12: =F10-F11 -> 82560000
B13: Saldo Kas ( B ) | E13: : | F13: =H23+H29+H31 -> 82560000
N14: =IF($J$3="","",IF($J$3="BOS REGULER",(VLOOKUP($J$5,Data!$B$9:$P$20,7,FALSE)),IF($J$3="SILPA REGULER",(VLOOKUP($J$5,Data!$B$24:$P$35,7,FALSE))))) -> 0
C15: Sado Kas B terdiri dari :
B16: 1. | C16: Lembaran uang kertas | D16: 100000 | E16: =N16 -> 0 | G16: Lembar | H16: =IF(E16="","",D16*E16) -> 0 | N16: =O16/D16 -> 0 | O16: =IF(N14>10000000,ROUNDDOWN(N14,-7),IF(N14<10000000,ROUNDDOWN(N14,-6),0)) -> 0 | P16: =N14-O16 -> 0
C17: Lembaran uang kertas | D17: 50000 | E17: =N17 -> 0 | G17: Lembar | H17: =IF(E17="","",D17*E17) -> 0 | N17: =O17/D17 -> 0 | O17: =IF(P16=0,0,IF(P16>50000,ROUNDDOWN(P16,-5))) -> 0 | P17: =P16-O17 -> 0
C18: Lembaran uang kertas | D18: 20000 | E18: =N18 -> 0 | G18: Lembar | H18: =IF(E18="","",D18*E18) -> 0 | N18: =O18/D18 -> 0 | O18: =IF(P17=0,0,IF(P17<20000,0,IF(P17<40000,20000,IF(P17<60000,40000,IF(P17<80000,60000,IF(P17<100000,80000)))))) -> 0 | P18: =P17-O18 -> 0
C19: Lembaran uang kertas | D19: 10000 | E19: =N19 -> 0 | G19: Lembar | H19: =IF(E19="","",D19*E19) -> 0 | N19: =O19/D19 -> 0 | O19: =IF(P18=0,0,IF(P18<100000,ROUNDDOWN(P18,-4))) -> 0 | P19: =P18-O19 -> 0
C20: Lembaran uang kertas | D20: 5000 | E20: =N20 -> 0 | G20: Lembar | H20: =IF(E20="","",D20*E20) -> 0 | N20: =O20/D20 -> 0 | O20: =IF(P19=0,0,IF(P19<5000,0,IF(P19<10000,5000,0))) -> 0 | P20: =P19-O20 -> 0
C21: Lembaran uang kertas | D21: 2000 | E21: =N21 -> 0 | G21: Lembar | H21: =IF(E21="","",D21*E21) -> 0 | N21: =O21/D21 -> 0 | O21: =IF(P20=0,0,IF(P20<2000,0,IF(P20<5000,2000))) -> 0 | P21: =P20-O21 -> 0
C22: Lembaran uang kertas | D22: 1000 | E22: =N22 -> 0 | G22: Lembar | H22: =IF(E22="","",D22*E22) -> 0 | N22: =O22/D22 -> 0 | O22: =IF(P21=0,0,IF(P21<1000,0,IF(P21<1900,1000))) -> 0 | P22: =P21-O22 -> 0
G23: Sub Jumlah (1) | H23: =SUM(H16:H22) -> 0
B25: 2. | C25: Keping uang logam | D25: 1000 | E25: 0 | G25: Keping | H25: =IF(E25="","",D25*E25) -> 0
C26: Keping uang logam | D26: 500 | E26: =N26 -> 0 | G26: Keping | H26: =IF(E26="","",D26*E26) -> 0 | N26: =O26/D26 -> 0 | O26: =IF(P22=0,0,IF(OR(P22<1000,500,P22<500,0),0)) -> 0 | P26: =P22-O26 -> 0
C27: Keping uang logam | D27: 200 | E27: =N27 -> 0 | G27: Keping | H27: =IF(E27="","",D27*E27) -> 0 | N27: =O27/D27 -> 0 | O27: =IF(P26=0,0,IF(P26<200,0,IF(P26<400,200,IF(P26<600,400,IF(P26<800,600,IF(P26<1000,800)))))) -> 0 | P27: =P26-O27 -> 0
C28: Keping uang logam | D28: 100 | E28: =N28 -> 0 | G28: Keping | H28: =IF(E28="","",D28*E28) -> 0 | N28: =O28/D28 -> 0 | O28: =IF(P27=0,0,IF(P27<500,ROUNDDOWN(P27,-2),IF(P27<100,0))) -> 0 | P28: =P27-O28 -> 0
G29: Sub Jumlah (2) | H29: =SUM(H25:H28) -> 0
B31: 3. | C31: Saldo Bank, Surat Berharga, dll. | G31: Sub Jumlah (3) | H31: =IF($J$3="","",IF($J$3="BOS REGULER",(VLOOKUP($J$5,Data!$B$9:$P$20,6,FALSE)),IF($J$3="SILPA REGULER",(VLOOKUP($J$5,Data!$B$24:$P$35,6,FALSE))))) -> 82560000
G33: Jumlah ( 1 + 2 + 3 ) | H33: =SUM(H23,H29,H31) -> 82560000
C35: Perbedaan (A - B) | H35: =F12-F13 -> 0
C37: Penjelasan Perbedaan | D37: =IF(H35=0,O37,N37) -> : ............................................................................................................... | N37: =": disebabkan tidak ada pecahan uang Rp "&TEXT(H35,"#.##0")&" rupiah pada saat transaksi." -> : disebabkan tidak ada pecahan uang Rp 0 rupiah pada saat transaksi. | O37: =": ..............................................................................................................." -> : ...............................................................................................................
G39: Tanggal : | H39: =F7 -> 46053
C40: Yang diperiksa, | H40: Yang memeriksa
C41: Bendahara/Pemegang Kas, | H41: Kepala Sekolah,
C47: =IF($J$3="","",IF($J$3="BOS REGULER",(VLOOKUP($J$5,Data!$B$9:$P$20,13,FALSE)),IF($J$3="SILPA REGULER",(VLOOKUP($J$5,Data!$B$24:$P$35,13,FALSE))))) -> AHMAD, S.Pd. | H47: =IF($J$3="","",IF($J$3="BOS REGULER",(VLOOKUP($J$5,Data!$B$9:$P$20,10,FALSE)),IF($J$3="SILPA REGULER",(VLOOKUP($J$5,Data!$B$24:$P$35,10,FALSE))))) -> YUNIARTI, S.Pd
C48: =IF($J$3="","","NIP. "&IF($J$3="BOS REGULER",(VLOOKUP($J$5,Data!$B$9:$P$20,14,FALSE)),IF($J$3="SILPA REGULER",(VLOOKUP($J$5,Data!$B$24:$P$35,14,FALSE))))) -> NIP. 196805251992121003 | H48: =IF($J$3="","","NIP. "&IF($J$3="BOS REGULER",(VLOOKUP($J$5,Data!$B$9:$P$20,11,FALSE)),IF($J$3="SILPA REGULER",(VLOOKUP($J$5,Data!$B$24:$P$35,11,FALSE))))) -> NIP. 196607071986102005

Sheet BA_Pemeriksaan Kas
B2: BERITA ACARA PEMERIKSAAN KAS
B3: =G3 -> BOS REGULER | G3: BOS REGULER
B4: ="PERIODE : BULAN "&G5&" "&2026 -> PERIODE : BULAN JUNI 2026 | G4: Pilih Bulan
G5: JUNI
B6: =IF($G$3="","",IF($G$3="BOS REGULER",(VLOOKUP($G$5,Data!$B$9:$Q$20,16,FALSE)),IF($G$3="SILPA REGULER",(VLOOKUP($G$5,Data!$B$24:$Q$35,16,FALSE))))) -> Pada hari ini Selasa tanggal tiga puluh bulan Juni tahun Dua ribu dua puluh enam. Yang bertanda tangan di bawah ini, kami Kepala Sekolah yang ditunjuk berdasarkan Surat Keputusan Nomor :
B7: =IF($G$3="","",IF($G$3="BOS REGULER",(VLOOKUP($G$5,Data!$B$9:$P$20,12,FALSE)),IF($G$3="SILPA REGULER",(VLOOKUP($G$5,Data!$B$24:$P$35,12,FALSE)))))&"." -> 800.1.13.3/062-BKPSDM tanggal 2 Januari 2026.
C9: Nama | D9: =": "&IF($G$3="","",IF($G$3="BOS REGULER",(VLOOKUP($G$5,Data!$B$9:$P$20,10,FALSE)),IF($G$3="SILPA REGULER",(VLOOKUP($G$5,Data!$B$24:$P$35,10,FALSE))))) -> : YUNIARTI, S.Pd
C10: Jabatan | D10: : Kepala Sekolah
B12: melakukan pemeriksaan kas kepada:
C14: Nama | D14: =": "&IF($G$3="","",IF($G$3="BOS REGULER",(VLOOKUP($G$5,Data!$B$9:$P$20,13,FALSE)),IF($G$3="SILPA REGULER",(VLOOKUP($G$5,Data!$B$24:$P$35,13,FALSE))))) -> : AHMAD, S.Pd.
C15: Jabatan | D15: : Bendahara
B17: ="yang berdasarkan Surat Keputusan Bupati Bandung Barat Nomor : "&IF($G$3="","",IF($G$3="BOS REGULER",(VLOOKUP($G$5,Data!$B$9:$P$20,15,FALSE)),IF($G$3="SILPA REGULER",(VLOOKUP($G$5,Data!$B$24:$P$35,15,FALSE)))))&" ditunjuk sebagai Bendahara Bantuan Operasional Sekolah Tingkat Sekolah Dasar Tahun Anggaran 2026." -> yang berdasarkan Surat Keputusan Bupati Bandung Barat Nomor : 100.3.3.2/Kep. - BKAD/2026 ditunjuk sebagai Bendahara Bantuan Operasional Sekolah Tingkat Sekolah Dasar Tahun Anggaran 2026.
B20: Berdasarkan pemeriksaan kas serta bukti-bukti dalam pengurusan itu, kami menemui kenyataan sebagai berikut:
B22: Jumlah uang yang dihitung dihadapan Bendahara/Pemegang Kas adalah :
B23: a) | C23: Uang kertas bank, uang logam | E23: =IF($G$3="","",IF($G$3="BOS REGULER",(VLOOKUP($G$5,Data!$B$9:$P$20,7,FALSE)),IF($G$3="SILPA REGULER",(VLOOKUP($G$5,Data!$B$24:$P$35,7,FALSE))))) -> 0
B24: b) | C24: Saldo Bank | E24: =IF($G$3="","",IF($G$3="BOS REGULER",(VLOOKUP($G$5,Data!$B$9:$P$20,6,FALSE)),IF($G$3="SILPA REGULER",(VLOOKUP($G$5,Data!$B$24:$P$35,6,FALSE))))) -> 0
B25: c) | C25: Surat berharga, dll. | E25: 0
D26: Jumlah | E26: =SUM(E23:E25) -> 0
B28: Saldo uang menurut Kas Umum | E28: =IF($G$3="","",IF($G$3="BOS REGULER",(VLOOKUP($G$5,Data!$B$9:$P$20,9,FALSE)),IF($G$3="SILPA REGULER",(VLOOKUP($G$5,Data!$B$24:$P$35,9,FALSE))))) -> 0
B29: Perbedaan antara saldo Kas dan saldo Buku | E29: =E28-E26 -> 0
E31: ="Tanggal : "&TEXT(IF($G$3="","",IF($G$3="BOS REGULER",(VLOOKUP($G$5,Data!$B$9:$P$20,3,FALSE)),IF($G$3="SILPA REGULER",(VLOOKUP($G$5,Data!$B$24:$P$35,3,FALSE))))),"dd mmmm yyyy") -> Tanggal : 30 June 2026
C32: Bendahara/Pemegang Kas, | E32: Kepala Sekolah,
C37: =IF($G$3="","",IF($G$3="BOS REGULER",(VLOOKUP($G$5,Data!$B$9:$P$20,13,FALSE)),IF($G$3="SILPA REGULER",(VLOOKUP($G$5,Data!$B$24:$P$35,13,FALSE))))) -> AHMAD, S.Pd. | E37: =IF($G$3="","",IF($G$3="BOS REGULER",(VLOOKUP($G$5,Data!$B$9:$P$20,10,FALSE)),IF($G$3="SILPA REGULER",(VLOOKUP($G$5,Data!$B$24:$P$35,10,FALSE))))) -> YUNIARTI, S.Pd
C38: =IF($G$3="","","NIP. "&IF($G$3="BOS REGULER",(VLOOKUP($G$5,Data!$B$9:$P$20,14,FALSE)),IF($G$3="SILPA REGULER",(VLOOKUP($G$5,Data!$B$24:$P$35,14,FALSE))))) -> NIP. 196805251992121003 | E38: =IF($G$3="","","NIP. "&IF($G$3="BOS REGULER",(VLOOKUP($G$5,Data!$B$9:$P$20,11,FALSE)),IF($G$3="SILPA REGULER",(VLOOKUP($G$5,Data!$B$24:$P$35,11,FALSE))))) -> NIP. 196607071986102005

Sheet Lbr. Pengaduan Masyarakat
A2: LEMBAR PENCATATAN PENGADUAN MASYARAKAT
A3: ="DANA "&E3&" TAHUN ANGGARAN 2024" -> DANA BOS REGULER TAHUN ANGGARAN 2024 | E3: BOS REGULER
A4: =IF(Data!C4="","",Data!C4&" KECAMATAN "&Data!C5) -> SD NEGERI PASIRHALANG KECAMATAN CIKALONGWETAN | E4: Pilih Bulan
A5: ="PERIODE : BULAN "&E5&" TAHUN 2024" -> PERIODE : BULAN JANUARI TAHUN 2024 | E5: JANUARI | G5: Januari | H5: Cikalongwetan, 31 Januari
G6: Februari | H6: Cikalongwetan, 28 Februari
A7: 1 | B7: Identitas Pengadu | G7: Maret | H7: Cikalongwetan, 30 Maret
B8: a. Nama | C8: : ................................................................................................................................ | G8: April | H8: Cikalongwetan, 30 April
B9: b. Alamat | C9: : ................................................................................................................................ | G9: Mei | H9: Cikalongwetan, 31 Mei
C10: ................................................................................................................................ | G10: Juni | H10: Cikalongwetan, 29 Juni
A11: 2 | B11: Tanggal Terima Pengaduan | C11: : ................................................................................................................................ | G11: Juli | H11: Cikalongwetan, 31 Juli
A12: 3 | B12: Lokasi Kejadian | G12: Agustus | H12: Cikalongwetan, 31 Agustus
B13: a. RT/RW/Dusun | C13: : ................................................................................................................................ | G13: September | H13: Cikalongwetan, 30 September
B14: b. Kelurahan | C14: : ................................................................................................................................ | G14: Oktober | H14: Cikalongwetan, 31 Oktober
B15: c. Kabupaten/Kota | C15: : ................................................................................................................................ | G15: November | H15: Cikalongwetan, 30 November
B16: d. Provinsi | C16: : ................................................................................................................................ | G16: Desember | H16: Cikalongwetan, 31 Desember
A17: 4 | B17: Uraian Pengaduan:
B18: ..........................................................................................................................................................................................
B19: ..........................................................................................................................................................................................
B20: ..........................................................................................................................................................................................
B21: ..........................................................................................................................................................................................
A22: 5 | B22: Tanggal Penyelidikan Dilakukan | C22: : ................................................................................................................................
A23: 6 | B23: Penyelidik | C23: : ................................................................................................................................
A24: 7 | B24: Temuan:
B25: ..........................................................................................................................................................................................
B26: ..........................................................................................................................................................................................
B27: ..........................................................................................................................................................................................
B28: ..........................................................................................................................................................................................
A29: 8 | B29: Keputusan/Rekomendasi:
B30: ..........................................................................................................................................................................................
B31: ..........................................................................................................................................................................................
B32: ..........................................................................................................................................................................................
A33: 9 | B33: Pelaksanaan Keputusan
B34: ..........................................................................................................................................................................................
B35: ..........................................................................................................................................................................................
B36: ..........................................................................................................................................................................................
A37: 10 | B37: Tanggal pemberitahuan kepada Pengadu tentang keputusan/dan pelaksanaan keputusan :
B38: ..........................................................................................................................................................................................
A39: 11 | B39: Dokumen yang diterima:
B40: ..........................................................................................................................................................................................
B41: ..........................................................................................................................................................................................
...

Sheet Lbr. Kritik-Saran
A3: LEMBAR PENCATATAN PERTANYAAN/KRITIK/SARAN | E3: BOS REGULER
A4: ="DANA "&E3&" TAHUN ANGGARAN 2024" -> DANA BOS REGULER TAHUN ANGGARAN 2024 | E4: Pilih Bulan
A5: =IF(Data!C4="","",Data!C4&" KECAMATAN "&Data!C5) -> SD NEGERI PASIRHALANG KECAMATAN CIKALONGWETAN | E5: JANUARI
A6: ="PERIODE : BULAN "&E5&" TAHUN 2024" -> PERIODE : BULAN JANUARI TAHUN 2024
G7: Januari | H7: Cikalongwetan, 31 Januari
G8: Februari | H8: Cikalongwetan, 28 Februari
A9: 1 | B9: Identitas Penanya/Pemberi Saran | G9: Maret | H9: Cikalongwetan, 30 Maret
B10: a. Nama | C10: : ........................................................................................................................ | G10: April | H10: Cikalongwetan, 30 April
B11: b. Alamat | C11: : ........................................................................................................................ | G11: Mei | H11: Cikalongwetan, 31 Mei
C12: ........................................................................................................................ | G12: Juni | H12: Cikalongwetan, 29 Juni
A13: 2 | B13: Tanggal Penerimaan Pertanyaan/Saran | C13: : ........................................................................................................................ | G13: Juli | H13: Cikalongwetan, 31 Juli
A14: 3 | B14: Uraian Pertanyaan/Saran: | G14: Agustus | H14: Cikalongwetan, 31 Agustus
B15: ............................................................................................................................................................................................. | G15: September | H15: Cikalongwetan, 30 September
B16: ............................................................................................................................................................................................. | G16: Oktober | H16: Cikalongwetan, 31 Oktober
B17: ............................................................................................................................................................................................. | G17: November | H17: Cikalongwetan, 30 November
B18: ............................................................................................................................................................................................. | G18: Desember | H18: Cikalongwetan, 31 Desember
B19: ............................................................................................................................................................................................. | G19: Desember | H19: Cikalongwetan, 31 Desember
B20: ............................................................................................................................................................................................. | G20: Desember | H20: Cikalongwetan, 31 Desember
B21: ............................................................................................................................................................................................. | G21: Desember | H21: Cikalongwetan, 31 Desember
B22: ............................................................................................................................................................................................. | G22: Desember | H22: Cikalongwetan, 31 Desember
B23: ............................................................................................................................................................................................. | G23: Desember | H23: Cikalongwetan, 31 Desember
A24: 4 | B24: Penerima Pertanyaan/Saran | C24: : ........................................................................................................................
A25: 5 | B25: Tindak Lanjut Saran:
B26: .............................................................................................................................................................................................
B27: .............................................................................................................................................................................................
B28: .............................................................................................................................................................................................
B29: .............................................................................................................................................................................................
B30: .............................................................................................................................................................................................
B31: .............................................................................................................................................................................................
B32: .............................................................................................................................................................................................
D34: ="Bandung Barat, "&TEXT(IF($E$3="","",IF($E$3="BOS REGULER",(VLOOKUP($E$5,Data!$B$9:$P$20,3,FALSE)),IF($E$3="SILPA REGULER",(VLOOKUP($E$5,Data!$B$24:$P$35,3,FALSE))))),"dd mmmm yyyy") -> Bandung Barat, 31 January 2026
D35: MELAPORKAN:
D36: Kepala Sekolah,
D41: =IF($E$3="","",IF($E$3="BOS REGULER",(VLOOKUP($E$5,Data!$B$9:$P$20,10,FALSE)),IF($E$3="SILPA REGULER",(VLOOKUP($E$5,Data!$B$24:$P$35,10,FALSE))))) -> YUNIARTI, S.Pd
D42: =IF($E$3="","","NIP. "&IF($E$3="BOS REGULER",(VLOOKUP($E$5,Data!$B$9:$P$20,11,FALSE)),IF($E$3="SILPA REGULER",(VLOOKUP($E$5,Data!$B$24:$P$35,11,FALSE))))) -> NIP. 196607071986102005
