Workbook
Name c_kegiatan: [1]!tbl_kegiatan[[#Headers],[Kegiatan]]
Name c_progrm: [1]!tbl_progrm[[#Headers],[No]]
Name c_stdr: [1]!tbl_stdr[[#Headers],[ID]]
Name list_Y_T: [1]!tbl_ya_tdk[tbl_ya_tdk]

Sheet Data
A1: Data
A3: Sekolah
A4: Kecamatan
A5: Kabupaten
A7: Kepala Sekolah
A8: NIP
A9: Bendahara
A10: NIP
A12: Honorarium
A13: Guru
A14: No | B14: Nama | D14: NUPTK | E14: JABATAN

Sheet Honor_guru
A1: DAFTAR PENERIMA HONORARIUM/GAJI GURU TIDAK TETAP (PEMBAYARAN NON TUNAI)
A2: BULAN JANUARI 2026
C4: Nomor | D4: : ____________________________ | N4: Program | O4: : 07 Pengembangan Standar Pembiayaan
C5: Nama Sekolah | D5: : SD NEGERI LEBAKLEUNGSIR | N5: Kegiatan | O5: : Pembayaran Honor Guru
C6: Kecamatan | D6: : Cikalongwetan | N6: Kode Rekening | O6: : 5.1.02.02.01.0013
C7: Kabupaten | D7: : Bandung Barat | N7: Kode Penggunaan | O7: : 12
A9: NO | B9: NAMA PTK | D9: NUPTK | E9: JABATAN | F9: Cost (Rp) | J9: JUMLAH (Rp) | K9: Gol. / Ruang | L9: VOLUME | N9: PPh 21 (non pegawai = 50% x PPh Bruto-PTKP (bulanan)) | O9: JUMLAH YANG DITERIMA (Rp) | P9: TANDA TANGAN
F10: Guru | G10: TAS/ Operator | H10: Pembina Ekskul
A11: 1 | B11: RACHMAWATI | D11: 9563779680230043 | E11: Guru Kelas | F11: 650000 | G11: 250000 | H11: 100000 | J11: =IF(B11="","",SUM(F11:I11)) -> 1000000 | K11: GTT | L11: 1 | M11: Bulan | N11: =IFERROR(J11*0/100,"") -> 0 | O11: =IFERROR(SUM(J11*L11)-N11,"") -> 1000000 | P11: 1 | Q11: 2
A12: 2 | J12: =IF(B12="","",SUM(F12:I12)) | N12: =IFERROR(J12*0/100,"") | O12: =IFERROR(SUM(J12*L12)-N12,"")
A13: 3 | J13: =IF(B13="","",SUM(F13:I13)) | N13: =IFERROR(J13*0/100,"") | O13: =IFERROR(SUM(J13*L13)-N13,"") | P13: 3 | Q13: 4
A14: 4 | J14: =IF(B14="","",SUM(F14:I14)) | N14: =IFERROR(J14*0/100,"") | O14: =IFERROR(SUM(J14*L14)-N14,"")
A15: 5 | J15: =IF(B15="","",SUM(F15:I15)) | N15: =IFERROR(J15*0/100,"") | O15: =IFERROR(SUM(J15*L15)-N15,"") | P15: 5 | Q15: 6
A16: 6 | J16: =IF(B16="","",SUM(F16:I16)) | N16: =IFERROR(J16*0/100,"") | O16: =IFERROR(SUM(J16*L16)-N16,"")
E17: JUMLAH | J17: =SUM(J11:J16) -> 1000000 | N17: =SUM(N11:N16) -> 0 | O17: =SUM(O11:O16) -> 1000000
P19: Cikalongwetan, 2 Januari 2026
C20: Mengetahui/Menyetujui | P20: Dibayar Lunas Tgl. 4 Februari 2026
C21: Kepala Sekolah, | P21: Bendahara BOS,
C27: BADRUDDIN, S.Ag. | P27: DEDE GUNAWAN, S.Pd.
C28: NIP. 197405082014121002 | P28: NIP. 198507172020121003
A36: DAFTAR PENERIMA HONORARIUM/GAJI GURU TIDAK TETAP (PEMBAYARAN NON TUNAI)
A37: BULAN FEBRUARI 2026
C39: Nomor | D39: : ____________________________ | N39: Program | O39: =O4 -> : 07 Pengembangan Standar Pembiayaan
C40: Nama Sekolah | D40: =D5 -> : SD NEGERI LEBAKLEUNGSIR | N40: Kegiatan | O40: =O5 -> : Pembayaran Honor Guru
C41: Kecamatan | D41: =D6 -> : Cikalongwetan | N41: Kode Rekening | O41: =O6 -> : 5.1.02.02.01.0013
C42: Kabupaten | D42: =D7 -> : Bandung Barat | N42: Kode Penggunaan | O42: =O7 -> : 12
A44: NO | B44: NAMA PTK | D44: NUPTK | E44: JABATAN | F44: Cost (Rp) | J44: JUMLAH (Rp) | K44: Gol. / Ruang | L44: VOLUME | N44: PPh 21 (non pegawai = 50% x PPh Bruto-PTKP (bulanan)) | O44: JUMLAH YANG DITERIMA (Rp) | P44: TANDA TANGAN
F45: Guru | G45: TAS/ Operator | H45: Pembina Ekskul
A46: 1 | B46: =IF(B11="","",B11) -> RACHMAWATI | D46: =IF(D11="","",D11) -> 9563779680230043 | E46: =IF(E11="","",E11) -> Guru Kelas | F46: =IF(F11="","",F11) -> 650000 | G46: =IF(G11="","",G11) -> 250000 | H46: =IF(H11="","",H11) -> 100000 | J46: =IF(B46="","",SUM(F46:I46)) -> 1000000 | K46: =IF(K11="","",K11) -> GTT | L46: =IF(L11="","",L11) -> 1 | M46: =IF(M11="","",M11) -> Bulan | N46: =IFERROR(J46*0/100,"") -> 0 | O46: =IFERROR(SUM(J46*L46)-N46,"") -> 1000000 | P46: 1 | Q46: 2
A47: 2 | B47: =IF(B12="","",B12) | D47: =IF(D12="","",D12) | E47: =IF(E12="","",E12) | F47: =IF(F12="","",F12) | G47: =IF(G12="","",G12) | H47: =IF(H12="","",H12) | J47: =IF(B47="","",SUM(F47:I47)) | K47: =IF(K12="","",K12) | L47: =IF(L12="","",L12) | M47: =IF(M12="","",M12) | N47: =IFERROR(J47*0/100,"") | O47: =IFERROR(SUM(J47*L47)-N47,"")
A48: 3 | B48: =IF(B13="","",B13) | D48: =IF(D13="","",D13) | E48: =IF(E13="","",E13) | F48: =IF(F13="","",F13) | G48: =IF(G13="","",G13) | H48: =IF(H13="","",H13) | J48: =IF(B48="","",SUM(F48:I48)) | K48: =IF(K13="","",K13) | L48: =IF(L13="","",L13) | M48: =IF(M13="","",M13) | N48: =IFERROR(J48*0/100,"") | O48: =IFERROR(SUM(J48*L48)-N48,"") | P48: 3 | Q48: 4
A49: 4 | B49: =IF(B14="","",B14) | D49: =IF(D14="","",D14) | E49: =IF(E14="","",E14) | F49: =IF(F14="","",F14) | G49: =IF(G14="","",G14) | H49: =IF(H14="","",H14) | J49: =IF(B49="","",SUM(F49:I49)) | K49: =IF(K14="","",K14) | L49: =IF(L14="","",L14) | M49: =IF(M14="","",M14) | N49: =IFERROR(J49*0/100,"") | O49: =IFERROR(SUM(J49*L49)-N49,"")
A50: 5 | B50: =IF(B15="","",B15) | D50: =IF(D15="","",D15) | E50: =IF(E15="","",E15) | F50: =IF(F15="","",F15) | G50: =IF(G15="","",G15) | H50: =IF(H15="","",H15) | J50: =IF(B50="","",SUM(F50:I50)) | K50: =IF(K15="","",K15) | L50: =IF(L15="","",L15) | M50: =IF(M15="","",M15) | N50: =IFERROR(J50*0/100,"") | O50: =IFERROR(SUM(J50*L50)-N50,"") | P50: 5 | Q50: 6
A51: 6 | B51: =IF(B16="","",B16) | D51: =IF(D16="","",D16) | E51: =IF(E16="","",E16) | F51: =IF(F16="","",F16) | G51: =IF(G16="","",G16) | H51: =IF(H16="","",H16) | J51: =IF(B51="","",SUM(F51:I51)) | K51: =IF(K16="","",K16) | L51: =IF(L16="","",L16) | M51: =IF(M16="","",M16) | N51: =IFERROR(J51*0/100,"") | O51: =IFERROR(SUM(J51*L51)-N51,"")
A52: JUMLAH | J52: =SUM(J46:J51) -> 1000000 | N52: =SUM(N46:N51) -> 0 | O52: =SUM(O46:O51) -> 1000000
P54: Cikalongwetan, 1 Februari 2026
C55: Mengetahui/Menyetujui | P55: Dibayar Lunas Tgl. 4 Februari 2026
C56: Kepala Sekolah, | P56: Bendahara BOS,
C62: =IF(C27="","",C27) -> BADRUDDIN, S.Ag. | P62: =IF(P27="","",P27) -> DEDE GUNAWAN, S.Pd.
C63: =IF(C28="","",C28) -> NIP. 197405082014121002 | P63: =IF(P28="","",P28) -> NIP. 198507172020121003
...

Sheet Honor_tendik
A1: DAFTAR PENERIMA HONORARIUM/GAJI TENAGA ADMINISTRASI SEKOLAH TIDAK TETAP (PEMBAYARAN NON TUNAI)
A2: =Honor_guru!A2 -> BULAN JANUARI 2026
C4: Nomor | D4: =Honor_guru!D4 -> : ____________________________ | M4: Program | N4: : 07 Pengembangan Standar Pembiayaan
C5: Nama Sekolah | D5: =Honor_guru!D5 -> : SD NEGERI LEBAKLEUNGSIR | M5: Kegiatan | N5: : Pembayaran Honor Tenaga Kependidikan
C6: Kecamatan | D6: =Honor_guru!D6 -> : Cikalongwetan | M6: Kode Rekening | N6: : 5.1.02.02.01.0013
C7: Kabupaten | D7: =Honor_guru!D7 -> : Bandung Barat | M7: Kode Penggunaan | N7: : 12
A9: NO | B9: NAMA PTK | D9: JABATAN | E9: Cost (Rp) | I9: JUMLAH (Rp) | J9: Gol. / Ruang | K9: VOLUME | M9: PPh 21 (non pegawai = 50% x PPh Bruto-PTKP (bulanan)) | N9: JUMLAH YANG DITERIMA (Rp) | O9: TANDA TANGAN
E10: TAS/ Operator | F10: Guru | G10: Pembina Ekskul | H10: Tenaga Perpustakaan
A11: 1 | I11: =IF(B11="","",SUM(E11:H11)) | J11: PTT | K11: 1 | L11: Bulan | M11: =IFERROR(I11*0/100,"") | N11: =IFERROR(SUM(I11*K11)-M11,"") | O11: 1 | P11: 2
A12: 2 | I12: =IF(B12="","",SUM(E12:H12)) | M12: =IFERROR(I12*0/100,"") | N12: =IFERROR(SUM(I12*K12)-M12,"")
A13: 3 | I13: =IF(B13="","",SUM(E13:H13)) | M13: =IFERROR(I13*0/100,"") | N13: =IFERROR(SUM(I13*K13)-M13,"") | O13: 3 | P13: 4
A14: 4 | I14: =IF(B14="","",SUM(E14:H14)) | M14: =IFERROR(I14*0/100,"") | N14: =IFERROR(SUM(I14*K14)-M14,"")
A15: 5 | I15: =IF(B15="","",SUM(E15:H15)) | M15: =IFERROR(I15*0/100,"") | N15: =IFERROR(SUM(I15*K15)-M15,"") | O15: 5 | P15: 6
A16: 6 | I16: =IF(B16="","",SUM(E16:H16)) | M16: =IFERROR(I16*0/100,"") | N16: =IFERROR(SUM(I16*K16)-M16,"")
A17: JUMLAH | I17: =SUM(I11:I16) -> 0 | M17: =SUM(M11:M16) -> 0 | N17: =SUM(N11:N16) -> 0
O19: =Honor_guru!P19 -> Cikalongwetan, 2 Januari 2026
C20: Mengetahui/Menyetujui | O20: =Honor_guru!P20 -> Dibayar Lunas Tgl. 4 Februari 2026
C21: Kepala Sekolah, | O21: Bendahara BOS,
C27: =Honor_guru!C27 -> BADRUDDIN, S.Ag. | O27: =Honor_guru!P27 -> DEDE GUNAWAN, S.Pd.
C28: =Honor_guru!C28 -> NIP. 197405082014121002 | O28: =Honor_guru!P28 -> NIP. 198507172020121003
A42: =$A$1 -> DAFTAR PENERIMA HONORARIUM/GAJI TENAGA ADMINISTRASI SEKOLAH TIDAK TETAP (PEMBAYARAN NON TUNAI)
A43: =Honor_guru!A37 -> BULAN FEBRUARI 2026
C45: Nomor | D45: : ____________________________ | M45: Program | N45: =N4 -> : 07 Pengembangan Standar Pembiayaan
C46: Nama Sekolah | D46: =D5 -> : SD NEGERI LEBAKLEUNGSIR | M46: Kegiatan | N46: =N5 -> : Pembayaran Honor Tenaga Kependidikan
C47: Kecamatan | D47: =D6 -> : Cikalongwetan | M47: Kode Rekening | N47: =N6 -> : 5.1.02.02.01.0013
C48: Kabupaten | D48: =D7 -> : Bandung Barat | M48: Kode Penggunaan | N48: =N7 -> : 12
A50: NO | B50: NAMA PTK | D50: JABATAN | E50: Cost (Rp) | I50: JUMLAH (Rp) | J50: Gol. / Ruang | K50: VOLUME | M50: PPh 21 (non pegawai = 50% x PPh Bruto-PTKP (bulanan)) | N50: JUMLAH YANG DITERIMA (Rp) | O50: TANDA TANGAN
E51: =IF(E10="","",E10) -> TAS/ Operator | F51: =IF(F10="","",F10) -> Guru | G51: =IF(G10="","",G10) -> Pembina Ekskul | H51: =IF(H10="","",H10) -> Tenaga Perpustakaan
A52: 1 | B52: =IF(B11="","",B11) | D52: =IF(D11="","",D11) | E52: =IF(E11="","",E11) | F52: =IF(F11="","",F11) | G52: =IF(G11="","",G11) | H52: =IF(H11="","",H11) | I52: =IF(B52="","",SUM(E52:H52)) | J52: =IF(J11="","",J11) -> PTT | K52: =IF(K11="","",K11) -> 1 | L52: =IF(L11="","",L11) -> Bulan | M52: =IFERROR(I52*0/100,"") | N52: =IFERROR(SUM(I52*K52)-M52,"") | O52: 1 | P52: 2
A53: 2 | B53: =IF(B12="","",B12) | D53: =IF(D12="","",D12) | E53: =IF(E12="","",E12) | F53: =IF(F12="","",F12) | G53: =IF(G12="","",G12) | H53: =IF(H12="","",H12) | I53: =IF(B53="","",SUM(E53:H53)) | J53: =IF(J12="","",J12) | K53: =IF(K12="","",K12) | L53: =IF(L12="","",L12) | M53: =IFERROR(I53*0/100,"") | N53: =IFERROR(SUM(I53*K53)-M53,"")
A54: 3 | B54: =IF(B13="","",B13) | D54: =IF(D13="","",D13) | E54: =IF(E13="","",E13) | F54: =IF(F13="","",F13) | G54: =IF(G13="","",G13) | H54: =IF(H13="","",H13) | I54: =IF(B54="","",SUM(E54:H54)) | J54: =IF(J13="","",J13) | K54: =IF(K13="","",K13) | L54: =IF(L13="","",L13) | M54: =IFERROR(I54*0/100,"") | N54: =IFERROR(SUM(I54*K54)-M54,"") | O54: 3 | P54: 4
A55: 4 | B55: =IF(B14="","",B14) | D55: =IF(D14="","",D14) | E55: =IF(E14="","",E14) | F55: =IF(F14="","",F14) | G55: =IF(G14="","",G14) | H55: =IF(H14="","",H14) | I55: =IF(B55="","",SUM(E55:H55)) | J55: =IF(J14="","",J14) | K55: =IF(K14="","",K14) | L55: =IF(L14="","",L14) | M55: =IFERROR(I55*0/100,"") | N55: =IFERROR(SUM(I55*K55)-M55,"")
A56: 5 | B56: =IF(B15="","",B15) | D56: =IF(D15="","",D15) | E56: =IF(E15="","",E15) | F56: =IF(F15="","",F15) | G56: =IF(G15="","",G15) | H56: =IF(H15="","",H15) | I56: =IF(B56="","",SUM(E56:H56)) | J56: =IF(J15="","",J15) | K56: =IF(K15="","",K15) | L56: =IF(L15="","",L15) | M56: =IFERROR(I56*0/100,"") | N56: =IFERROR(SUM(I56*K56)-M56,"") | O56: 5 | P56: 6
A57: 6 | B57: =IF(B16="","",B16) | D57: =IF(D16="","",D16) | E57: =IF(E16="","",E16) | F57: =IF(F16="","",F16) | G57: =IF(G16="","",G16) | H57: =IF(H16="","",H16) | I57: =IF(B57="","",SUM(E57:H57)) | J57: =IF(J16="","",J16) | K57: =IF(K16="","",K16) | L57: =IF(L16="","",L16) | M57: =IFERROR(I57*0/100,"") | N57: =IFERROR(SUM(I57*K57)-M57,"")
A58: JUMLAH | I58: =SUM(I52:I57) -> 0 | M58: =SUM(M52:M57) -> 0 | N58: =SUM(N52:N57) -> 0
O60: =Honor_guru!P54 -> Cikalongwetan, 1 Februari 2026
C61: Mengetahui/Menyetujui | O61: =Honor_guru!P55 -> Dibayar Lunas Tgl. 4 Februari 2026
C62: Kepala Sekolah, | O62: Bendahara BOS,
C68: =IF(C27="","",C27) -> BADRUDDIN, S.Ag. | O68: =IF(O27="","",O27) -> DEDE GUNAWAN, S.Pd.
C69: =IF(C28="","",C28) -> NIP. 197405082014121002 | O69: =IF(O28="","",O28) -> NIP. 198507172020121003
...

Sheet Honor_Perpus
A1: DAFTAR PENERIMA HONORARIUM/GAJI TENAGA PERPUSTAKAAN TIDAK TETAP (PEMBAYARAN NON TUNAI)
A2: =Honor_guru!A2 -> BULAN JANUARI 2026
C4: Nomor | D4: =Honor_guru!D4 -> : ____________________________ | M4: Program | N4: : 07 Pengembangan Standar Pembiayaan
C5: Nama Sekolah | D5: =Honor_guru!D5 -> : SD NEGERI LEBAKLEUNGSIR | M5: Kegiatan | N5: : Pembayaran Honor (Tenaga Perpustakaan)
C6: Kecamatan | D6: =Honor_guru!D6 -> : Cikalongwetan | M6: Kode Rekening | N6: : 5.1.02.02.01.0013
C7: Kabupaten | D7: =Honor_guru!D7 -> : Bandung Barat | M7: Kode Penggunaan | N7: : 12
A9: NO | B9: NAMA PTK | D9: JABATAN | E9: Cost (Rp) | I9: JUMLAH (Rp) | J9: Gol. / Ruang | K9: VOLUME | M9: PPh 21 (non pegawai = 50% x PPh Bruto-PTKP (bulanan)) | N9: JUMLAH YANG DITERIMA (Rp) | O9: TANDA TANGAN
E10: Tenaga Perpustakaan | F10: Pembina Ekskul | G10: Guru | H10: TAS/ Operator
A11: 1 | B11: LINDAWATI | D11: Tenaga Perpustakaan | E11: 700000 | G11: - | I11: =IF(B11="","",SUM(E11:H11)) -> 700000 | J11: PTT | K11: 1 | L11: Bulan | M11: =IFERROR(I11*0/100,"") -> 0 | N11: =IFERROR(SUM(I11*K11)-M11,"") -> 700000 | O11: 1 | P11: 2
A12: 2 | I12: =IF(B12="","",SUM(E12:H12)) | M12: =IFERROR(I12*0/100,"") | N12: =IFERROR(SUM(I12*K12)-M12,"")
A13: 3 | I13: =IF(B13="","",SUM(E13:H13)) | M13: =IFERROR(I13*0/100,"") | N13: =IFERROR(SUM(I13*K13)-M13,"") | O13: 3 | P13: 4
A14: 4 | I14: =IF(B14="","",SUM(E14:H14)) | M14: =IFERROR(I14*0/100,"") | N14: =IFERROR(SUM(I14*K14)-M14,"")
A15: 5 | I15: =IF(B15="","",SUM(E15:H15)) | M15: =IFERROR(I15*0/100,"") | N15: =IFERROR(SUM(I15*K15)-M15,"") | O15: 5 | P15: 6
A16: 6 | I16: =IF(B16="","",SUM(E16:H16)) | M16: =IFERROR(I16*0/100,"") | N16: =IFERROR(SUM(I16*K16)-M16,"")
D17: JUMLAH | I17: =SUM(I11:I16) -> 700000 | M17: =SUM(M11:M16) -> 0 | N17: =SUM(N11:N16) -> 700000
O19: =Honor_guru!P19 -> Cikalongwetan, 2 Januari 2026
C20: Mengetahui/Menyetujui | O20: =Honor_guru!P20 -> Dibayar Lunas Tgl. 4 Februari 2026
C21: Kepala Sekolah, | O21: Bendahara BOS,
C27: =Honor_guru!C27 -> BADRUDDIN, S.Ag. | O27: =Honor_guru!P27 -> DEDE GUNAWAN, S.Pd.
C28: =Honor_guru!C28 -> NIP. 197405082014121002 | O28: =Honor_guru!P28 -> NIP. 198507172020121003
A36: =$A$1 -> DAFTAR PENERIMA HONORARIUM/GAJI TENAGA PERPUSTAKAAN TIDAK TETAP (PEMBAYARAN NON TUNAI)
A37: =Honor_guru!A37 -> BULAN FEBRUARI 2026
C39: Nomor | D39: : ____________________________ | M39: Program | N39: =N4 -> : 07 Pengembangan Standar Pembiayaan
C40: Nama Sekolah | D40: =D5 -> : SD NEGERI LEBAKLEUNGSIR | M40: Kegiatan | N40: =N5 -> : Pembayaran Honor (Tenaga Perpustakaan)
C41: Kecamatan | D41: =D6 -> : Cikalongwetan | M41: Kode Rekening | N41: =N6 -> : 5.1.02.02.01.0013
C42: Kabupaten | D42: =D7 -> : Bandung Barat | M42: Kode Penggunaan | N42: =N7 -> : 12
A44: NO | B44: NAMA PTK | D44: JABATAN | E44: Cost (Rp) | I44: JUMLAH (Rp) | J44: Gol. / Ruang | K44: VOLUME | M44: PPh 21 (non pegawai = 50% x PPh Bruto-PTKP (bulanan)) | N44: JUMLAH YANG DITERIMA (Rp) | O44: TANDA TANGAN
E45: =IF(E10="","",E10) -> Tenaga Perpustakaan | F45: =IF(F10="","",F10) -> Pembina Ekskul | G45: =IF(G10="","",G10) -> Guru | H45: =IF(H10="","",H10) -> TAS/ Operator
A46: 1 | B46: =IF(B11="","",B11) -> LINDAWATI | D46: =IF(D11="","",D11) -> Tenaga Perpustakaan | E46: =IF(E11="","",E11) -> 700000 | F46: =IF(F11="","",F11) | G46: =IF(G11="","",G11) -> - | H46: =IF(H11="","",H11) | I46: =IF(B46="","",SUM(E46:H46)) -> 700000 | J46: =IF(J11="","",J11) -> PTT | K46: =IF(K11="","",K11) -> 1 | L46: =IF(L11="","",L11) -> Bulan | M46: =IFERROR(I46*0/100,"") -> 0 | N46: =IFERROR(SUM(I46*K46)-M46,"") -> 700000 | O46: 1 | P46: 2
A47: 2 | B47: =IF(B12="","",B12) | D47: =IF(D12="","",D12) | E47: =IF(E12="","",E12) | F47: =IF(F12="","",F12) | G47: =IF(G12="","",G12) | H47: =IF(H12="","",H12) | I47: =IF(B47="","",SUM(E47:H47)) | J47: =IF(J12="","",J12) | K47: =IF(K12="","",K12) | L47: =IF(L12="","",L12) | M47: =IFERROR(I47*0/100,"") | N47: =IFERROR(SUM(I47*K47)-M47,"")
A48: 3 | B48: =IF(B13="","",B13) | D48: =IF(D13="","",D13) | E48: =IF(E13="","",E13) | F48: =IF(F13="","",F13) | G48: =IF(G13="","",G13) | H48: =IF(H13="","",H13) | I48: =IF(B48="","",SUM(E48:H48)) | J48: =IF(J13="","",J13) | K48: =IF(K13="","",K13) | L48: =IF(L13="","",L13) | M48: =IFERROR(I48*0/100,"") | N48: =IFERROR(SUM(I48*K48)-M48,"") | O48: 3 | P48: 4
A49: 4 | B49: =IF(B14="","",B14) | D49: =IF(D14="","",D14) | E49: =IF(E14="","",E14) | F49: =IF(F14="","",F14) | G49: =IF(G14="","",G14) | H49: =IF(H14="","",H14) | I49: =IF(B49="","",SUM(E49:H49)) | J49: =IF(J14="","",J14) | K49: =IF(K14="","",K14) | L49: =IF(L14="","",L14) | M49: =IFERROR(I49*0/100,"") | N49: =IFERROR(SUM(I49*K49)-M49,"")
A50: 5 | B50: =IF(B15="","",B15) | D50: =IF(D15="","",D15) | E50: =IF(E15="","",E15) | F50: =IF(F15="","",F15) | G50: =IF(G15="","",G15) | H50: =IF(H15="","",H15) | I50: =IF(B50="","",SUM(E50:H50)) | J50: =IF(J15="","",J15) | K50: =IF(K15="","",K15) | L50: =IF(L15="","",L15) | M50: =IFERROR(I50*0/100,"") | N50: =IFERROR(SUM(I50*K50)-M50,"") | O50: 5 | P50: 6
A51: 6 | B51: =IF(B16="","",B16) | D51: =IF(D16="","",D16) | E51: =IF(E16="","",E16) | F51: =IF(F16="","",F16) | G51: =IF(G16="","",G16) | H51: =IF(H16="","",H16) | I51: =IF(B51="","",SUM(E51:H51)) | J51: =IF(J16="","",J16) | K51: =IF(K16="","",K16) | L51: =IF(L16="","",L16) | M51: =IFERROR(I51*0/100,"") | N51: =IFERROR(SUM(I51*K51)-M51,"")
A52: JUMLAH | I52: =SUM(I46:I51) -> 700000 | M52: =SUM(M46:M51) -> 0 | N52: =SUM(N46:N51) -> 700000
O54: =Honor_guru!P54 -> Cikalongwetan, 1 Februari 2026
C55: Mengetahui/Menyetujui | O55: =Honor_guru!P55 -> Dibayar Lunas Tgl. 4 Februari 2026
C56: Kepala Sekolah, | O56: Bendahara BOS,
C62: =IF(C27="","",C27) -> BADRUDDIN, S.Ag. | O62: =IF(O27="","",O27) -> DEDE GUNAWAN, S.Pd.
C63: =IF(C28="","",C28) -> NIP. 197405082014121002 | O63: =IF(O28="","",O28) -> NIP. 198507172020121003
...

Sheet Honor_penjaga
A1: DAFTAR PENERIMA HONORARIUM/GAJI PENJAGA SEKOLAH TIDAK TETAP (PEMBAYARAN NON TUNAI)
A2: =Honor_guru!A2 -> BULAN JANUARI 2026
C4: Nomor | D4: =Honor_tendik!D4 -> : ____________________________ | M4: Program | N4: : 07 Pengembangan Standar Pembiayaan
C5: Nama Sekolah | D5: =Honor_tendik!D5 -> : SD NEGERI LEBAKLEUNGSIR | M5: Kegiatan | N5: : Pembayaran Honor (Penjaga)
C6: Kecamatan | D6: =Honor_tendik!D6 -> : Cikalongwetan | M6: Kode Rekening | N6: : 5.1.02.02.01.0013
C7: Kabupaten | D7: =Honor_tendik!D7 -> : Bandung Barat | M7: Kode Penggunaan | N7: : 12
A9: NO | B9: NAMA PTK | D9: JABATAN | E9: Cost (Rp) | I9: JUMLAH (Rp) | J9: Gol. / Ruang | K9: VOLUME | M9: PPh 21 (non pegawai = 50% x PPh Bruto-PTKP (bulanan)) | N9: JUMLAH YANG DITERIMA (Rp) | O9: TANDA TANGAN
E10: Penjaga | F10: Guru | G10: Pembina Ekskul | H10: Tenaga Perpustakaan
A11: 1 | B11: USEP PUDIN | D11: Penjaga Sekolah | E11: 750000 | I11: =IF(B11="","",SUM(E11:H11)) -> 750000 | J11: PTT | K11: 1 | L11: Bulan | M11: =IFERROR(I11*0/100,"") -> 0 | N11: =IFERROR(SUM(I11*K11)-M11,"") -> 750000 | O11: 1 | P11: 2
A12: 2 | I12: =IF(B12="","",SUM(E12:H12)) | M12: =IFERROR(I12*0/100,"") | N12: =IFERROR(SUM(I12*K12)-M12,"")
A13: 3 | I13: =IF(B13="","",SUM(E13:H13)) | M13: =IFERROR(I13*0/100,"") | N13: =IFERROR(SUM(I13*K13)-M13,"") | O13: 3 | P13: 4
A14: 4 | I14: =IF(B14="","",SUM(E14:H14)) | M14: =IFERROR(I14*0/100,"") | N14: =IFERROR(SUM(I14*K14)-M14,"")
A15: 5 | I15: =IF(B15="","",SUM(E15:H15)) | M15: =IFERROR(I15*0/100,"") | N15: =IFERROR(SUM(I15*K15)-M15,"") | O15: 5 | P15: 6
A16: 6 | I16: =IF(B16="","",SUM(E16:H16)) | M16: =IFERROR(I16*0/100,"") | N16: =IFERROR(SUM(I16*K16)-M16,"")
A17: JUMLAH | I17: =SUM(I11:I16) -> 750000 | M17: =SUM(M11:M16) -> 0 | N17: =SUM(N11:N16) -> 750000
O19: =Honor_guru!P19 -> Cikalongwetan, 2 Januari 2026
C20: Mengetahui/Menyetujui | O20: =Honor_guru!P20 -> Dibayar Lunas Tgl. 4 Februari 2026
C21: Kepala Sekolah, | O21: Bendahara BOS,
C27: =Honor_guru!C27 -> BADRUDDIN, S.Ag. | O27: =Honor_guru!P27 -> DEDE GUNAWAN, S.Pd.
C28: =Honor_guru!C28 -> NIP. 197405082014121002 | O28: =Honor_guru!P28 -> NIP. 198507172020121003
A37: =$A$1 -> DAFTAR PENERIMA HONORARIUM/GAJI PENJAGA SEKOLAH TIDAK TETAP (PEMBAYARAN NON TUNAI)
A38: =Honor_guru!A37 -> BULAN FEBRUARI 2026
C40: Nomor | D40: : ____________________________ | M40: Program | N40: =N4 -> : 07 Pengembangan Standar Pembiayaan
C41: Nama Sekolah | D41: =D5 -> : SD NEGERI LEBAKLEUNGSIR | M41: Kegiatan | N41: =N5 -> : Pembayaran Honor (Penjaga)
C42: Kecamatan | D42: =D6 -> : Cikalongwetan | M42: Kode Rekening | N42: =N6 -> : 5.1.02.02.01.0013
C43: Kabupaten | D43: =D7 -> : Bandung Barat | M43: Kode Penggunaan | N43: =N7 -> : 12
A45: NO | B45: NAMA PTK | D45: JABATAN | E45: Cost (Rp) | I45: JUMLAH (Rp) | J45: Gol. / Ruang | K45: VOLUME | M45: PPh 21 (non pegawai = 50% x PPh Bruto-PTKP (bulanan)) | N45: JUMLAH YANG DITERIMA (Rp) | O45: TANDA TANGAN
E46: =IF(E10="","",E10) -> Penjaga | F46: =IF(F10="","",F10) -> Guru | G46: =IF(G10="","",G10) -> Pembina Ekskul | H46: =IF(H10="","",H10) -> Tenaga Perpustakaan
A47: 1 | B47: =IF(B11="","",B11) -> USEP PUDIN | D47: =IF(D11="","",D11) -> Penjaga Sekolah | E47: =IF(E11="","",E11) -> 750000 | F47: =IF(F11="","",F11) | G47: =IF(G11="","",G11) | H47: =IF(H11="","",H11) | I47: =IF(B47="","",SUM(E47:H47)) -> 750000 | J47: =IF(J11="","",J11) -> PTT | K47: =IF(K11="","",K11) -> 1 | L47: =IF(L11="","",L11) -> Bulan | M47: =IFERROR(I47*0/100,"") -> 0 | N47: =IFERROR(SUM(I47*K47)-M47,"") -> 750000 | O47: 1 | P47: 2
A48: 2 | B48: =IF(B12="","",B12) | D48: =IF(D12="","",D12) | E48: =IF(E12="","",E12) | F48: =IF(F12="","",F12) | G48: =IF(G12="","",G12) | H48: =IF(H12="","",H12) | I48: =IF(B48="","",SUM(E48:H48)) | J48: =IF(J12="","",J12) | K48: =IF(K12="","",K12) | L48: =IF(L12="","",L12) | M48: =IFERROR(I48*0/100,"") | N48: =IFERROR(SUM(I48*K48)-M48,"")
A49: 3 | B49: =IF(B13="","",B13) | D49: =IF(D13="","",D13) | E49: =IF(E13="","",E13) | F49: =IF(F13="","",F13) | G49: =IF(G13="","",G13) | H49: =IF(H13="","",H13) | I49: =IF(B49="","",SUM(E49:H49)) | J49: =IF(J13="","",J13) | K49: =IF(K13="","",K13) | L49: =IF(L13="","",L13) | M49: =IFERROR(I49*0/100,"") | N49: =IFERROR(SUM(I49*K49)-M49,"") | O49: 3 | P49: 4
A50: 4 | B50: =IF(B14="","",B14) | D50: =IF(D14="","",D14) | E50: =IF(E14="","",E14) | F50: =IF(F14="","",F14) | G50: =IF(G14="","",G14) | H50: =IF(H14="","",H14) | I50: =IF(B50="","",SUM(E50:H50)) | J50: =IF(J14="","",J14) | K50: =IF(K14="","",K14) | L50: =IF(L14="","",L14) | M50: =IFERROR(I50*0/100,"") | N50: =IFERROR(SUM(I50*K50)-M50,"")
A51: 5 | B51: =IF(B15="","",B15) | D51: =IF(D15="","",D15) | E51: =IF(E15="","",E15) | F51: =IF(F15="","",F15) | G51: =IF(G15="","",G15) | H51: =IF(H15="","",H15) | I51: =IF(B51="","",SUM(E51:H51)) | J51: =IF(J15="","",J15) | K51: =IF(K15="","",K15) | L51: =IF(L15="","",L15) | M51: =IFERROR(I51*0/100,"") | N51: =IFERROR(SUM(I51*K51)-M51,"") | O51: 5 | P51: 6
A52: 6 | B52: =IF(B16="","",B16) | D52: =IF(D16="","",D16) | E52: =IF(E16="","",E16) | F52: =IF(F16="","",F16) | G52: =IF(G16="","",G16) | H52: =IF(H16="","",H16) | I52: =IF(B52="","",SUM(E52:H52)) | J52: =IF(J16="","",J16) | K52: =IF(K16="","",K16) | L52: =IF(L16="","",L16) | M52: =IFERROR(I52*0/100,"") | N52: =IFERROR(SUM(I52*K52)-M52,"")
A53: JUMLAH | I53: =SUM(I47:I52) -> 750000 | M53: =SUM(M47:M52) -> 0 | N53: =SUM(N47:N52) -> 750000
O55: =Honor_guru!P54 -> Cikalongwetan, 1 Februari 2026
C56: Mengetahui/Menyetujui | O56: =Honor_guru!P55 -> Dibayar Lunas Tgl. 4 Februari 2026
C57: Kepala Sekolah, | O57: Bendahara BOS,
C63: =IF(C27="","",C27) -> BADRUDDIN, S.Ag. | O63: =IF(O27="","",O27) -> DEDE GUNAWAN, S.Pd.
C64: =IF(C28="","",C28) -> NIP. 197405082014121002 | O64: =IF(O28="","",O28) -> NIP. 198507172020121003
...

Sheet Transpor_bank
A1: DAFTAR BUKTI PENERIMA PERJALANAN DINAS KE BANK (Transaksi Non Tunai)
A2: =Honor_guru!A2 -> BULAN JANUARI 2026
C4: Nomor | D4: =Honor_penjaga!D4 -> : ____________________________ | I4: Program | J4: : 07 Pengembangan Standar Pembiayaan
C5: Nama Sekolah | D5: =Honor_penjaga!D5 -> : SD NEGERI LEBAKLEUNGSIR | I5: Kegiatan | J5: : Perjalanan Dinas ke bank
C6: Kecamatan | D6: =Honor_penjaga!D6 -> : Cikalongwetan | I6: Kode Rekening | J6: : 5.1.02.04.01.0003
C7: Kabupaten | D7: =Honor_penjaga!D7 -> : Bandung Barat | I7: Kode Penggunaan | J7: : 5
A9: NO | B9: NAMA PTK | D9: JABATAN | E9: Gol. / Ruang | F9: VOL | G9: SATUAN | H9: UNIT COST (Rp) | I9: JUMLAH (Rp) | J9: TANDA TANGAN
A10: 1 | B10: DEDE GUNAWAN | D10: Guru/Bendahara | E10: III/b | F10: 2 | G10: Perjalanan | H10: 75000 | I10: =F10*H10 -> 150000 | J10: 1 | K10: 2
A11: 2 | I11: =F11*H11 -> 0
A12: 3 | I12: =F12*H12 -> 0 | J12: 3 | K12: 4
A13: 4 | I13: =F13*H13 -> 0
A14: JUMLAH | I14: =SUM(I10:I13) -> 150000
J16: =Honor_guru!P19 -> Cikalongwetan, 2 Januari 2026
C17: Mengetahui/Menyetujui | J17: =Honor_guru!P20 -> Dibayar Lunas Tgl. 4 Februari 2026
C18: Kepala Sekolah, | J18: Bendahara BOS,
C24: =Honor_guru!C27 -> BADRUDDIN, S.Ag. | J24: =Honor_guru!P27 -> DEDE GUNAWAN, S.Pd.
C25: =Honor_guru!C28 -> NIP. 197405082014121002 | J25: =Honor_guru!P28 -> NIP. 198507172020121003
A33: =$A$1 -> DAFTAR BUKTI PENERIMA PERJALANAN DINAS KE BANK (Transaksi Non Tunai)
A34: =Honor_guru!A37 -> BULAN FEBRUARI 2026
C36: Nomor | D36: : _____________________________ | I36: Program | J36: =J4 -> : 07 Pengembangan Standar Pembiayaan
C37: Nama Sekolah | D37: =D5 -> : SD NEGERI LEBAKLEUNGSIR | I37: Kegiatan | J37: =J5 -> : Perjalanan Dinas ke bank
C38: Kecamatan | D38: =D6 -> : Cikalongwetan | I38: Kode Rekening | J38: =J6 -> : 5.1.02.04.01.0003
C39: Kabupaten | D39: =D7 -> : Bandung Barat | I39: Kode Penggunaan | J39: =J7 -> : 5
A41: NO | B41: NAMA PTK | D41: JABATAN | E41: Gol. / Ruang | F41: VOL | G41: SATUAN | H41: UNIT COST (Rp) | I41: JUMLAH (Rp) | J41: TANDA TANGAN
A42: 1 | B42: =IF(B10="","",B10) -> DEDE GUNAWAN | D42: =IF(D10="","",D10) -> Guru/Bendahara | E42: =IF(E10="","",E10) -> III/b | F42: =IF(F10="","",F10) -> 2 | G42: =IF(G10="","",G10) -> Perjalanan | H42: =IF(H10="","",H10) -> 75000 | I42: =IFERROR(SUM(F42*H42),"") -> 150000 | J42: 1 | K42: 2
A43: 2 | B43: =IF(B11="","",B11) | D43: =IF(D11="","",D11) | E43: =IF(E11="","",E11) | F43: =IF(F11="","",F11) | G43: =IF(G11="","",G11) | H43: =IF(H11="","",H11) | I43: =IFERROR(SUM(F43*H43),"")
A44: 3 | B44: =IF(B12="","",B12) | D44: =IF(D12="","",D12) | E44: =IF(E12="","",E12) | F44: =IF(F12="","",F12) | G44: =IF(G12="","",G12) | H44: =IF(H12="","",H12) | I44: =IFERROR(SUM(F44*H44),"") | J44: 3 | K44: 4
A45: 4 | B45: =IF(B13="","",B13) | D45: =IF(D13="","",D13) | E45: =IF(E13="","",E13) | F45: =IF(F13="","",F13) | G45: =IF(G13="","",G13) | H45: =IF(H13="","",H13) | I45: =IFERROR(SUM(F45*H45),"")
A46: JUMLAH | I46: =SUM(I42:I45) -> 150000
J48: Cikalongwetan, 4 Februari 2026
C49: Mengetahui/Menyetujui | J49: =Honor_guru!P55 -> Dibayar Lunas Tgl. 4 Februari 2026
C50: Kepala Sekolah, | J50: Bendahara BOS,
C56: =C24 -> BADRUDDIN, S.Ag. | J56: =J24 -> DEDE GUNAWAN, S.Pd.
C57: =C25 -> NIP. 197405082014121002 | J57: =J25 -> NIP. 198507172020121003
A65: =$A$1 -> DAFTAR BUKTI PENERIMA PERJALANAN DINAS KE BANK (Transaksi Non Tunai)
A66: =Honor_guru!A73 -> BULAN MARET 2026
C68: Nomor | D68: : _____________________________ | I68: Program | J68: =J36 -> : 07 Pengembangan Standar Pembiayaan
C69: Nama Sekolah | D69: =D37 -> : SD NEGERI LEBAKLEUNGSIR | I69: Kegiatan | J69: =J37 -> : Perjalanan Dinas ke bank
C70: Kecamatan | D70: =D38 -> : Cikalongwetan | I70: Kode Rekening | J70: =J38 -> : 5.1.02.04.01.0003
C71: Kabupaten | D71: =D39 -> : Bandung Barat | I71: Kode Penggunaan | J71: =J39 -> : 5
...

Sheet Transpor_koordinasi
A1: DAFTAR BUKTI PENERIMA PERJALANAN DINAS KOORDINASI PENGELOLAAN DANA BOSP (Transaksi Non Tunai)
A2: =Transpor_bank!A2 -> BULAN JANUARI 2026
C4: Nomor | D4: =Transpor_bank!D4 -> : ____________________________ | I4: Program | J4: : 06 Pengembangan Standar Pengelolaan
C5: Nama Sekolah | D5: =Transpor_bank!D5 -> : SD NEGERI LEBAKLEUNGSIR | I5: Kegiatan | J5: : Perjalanan Dinas koordinasi
C6: Kecamatan | D6: =Transpor_bank!D6 -> : Cikalongwetan | I6: Kode Rekening | J6: : 5.1.02.04.01.0003
C7: Kabupaten | D7: =Transpor_bank!D7 -> : Bandung Barat | I7: Kode Penggunaan | J7: : 5
A9: NO | B9: NAMA PTK | D9: JABATAN | E9: Gol. / Ruang | F9: VOL | G9: SATUAN | H9: UNIT COST (Rp) | I9: JUMLAH (Rp) | J9: TANDA TANGAN
A10: 1 | B10: DEDE GUNAWAN | D10: Bendahara | E10: III/b | F10: 1 | G10: Perjalanan | H10: 150000 | I10: =F10*H10 -> 150000 | J10: 1 | K10: 2
A11: 2 | I11: =F11*H11 -> 0
A12: 3 | I12: =F12*H12 -> 0 | J12: 3 | K12: 4
A13: 4 | I13: =F13*H13 -> 0
A14: JUMLAH | I14: =SUM(I10:I13) -> 150000
J16: =Transpor_bank!J16 -> Cikalongwetan, 2 Januari 2026
C17: Mengetahui/Menyetujui | J17: =Transpor_bank!J17 -> Dibayar Lunas Tgl. 4 Februari 2026
C18: Kepala Sekolah, | J18: Bendahara BOS,
C24: =Transpor_bank!C24 -> BADRUDDIN, S.Ag. | J24: =Transpor_bank!J24 -> DEDE GUNAWAN, S.Pd.
C25: =Transpor_bank!C25 -> NIP. 197405082014121002 | J25: =Transpor_bank!J25 -> NIP. 198507172020121003
A33: =$A$1 -> DAFTAR BUKTI PENERIMA PERJALANAN DINAS KOORDINASI PENGELOLAAN DANA BOSP (Transaksi Non Tunai)
A34: =Transpor_bank!A34 -> BULAN FEBRUARI 2026
C36: Nomor | D36: : _____________________________ | I36: Program | J36: =J4 -> : 06 Pengembangan Standar Pengelolaan
C37: Nama Sekolah | D37: =D5 -> : SD NEGERI LEBAKLEUNGSIR | I37: Kegiatan | J37: =J5 -> : Perjalanan Dinas koordinasi
C38: Kecamatan | D38: =D6 -> : Cikalongwetan | I38: Kode Rekening | J38: =J6 -> : 5.1.02.04.01.0003
C39: Kabupaten | D39: =D7 -> : Bandung Barat | I39: Kode Penggunaan | J39: =J7 -> : 5
A41: NO | B41: NAMA PTK | D41: JABATAN | E41: Gol. / Ruang | F41: VOL | G41: SATUAN | H41: UNIT COST (Rp) | I41: JUMLAH (Rp) | J41: TANDA TANGAN
A42: 1 | B42: =IF(B10="","",B10) -> DEDE GUNAWAN | D42: =IF(D10="","",D10) -> Bendahara | E42: =IF(E10="","",E10) -> III/b | F42: 3 | G42: =IF(G10="","",G10) -> Perjalanan | H42: =IF(H10="","",H10) -> 150000 | I42: =IFERROR(SUM(F42*H42),"") -> 450000 | J42: 1 | K42: 2
A43: 2 | B43: =IF(B11="","",B11) | D43: =IF(D11="","",D11) | E43: =IF(E11="","",E11) | F43: =IF(F11="","",F11) | G43: =IF(G11="","",G11) | H43: =IF(H11="","",H11) | I43: =IFERROR(SUM(F43*H43),"")
A44: 3 | B44: =IF(B12="","",B12) | D44: =IF(D12="","",D12) | E44: =IF(E12="","",E12) | F44: =IF(F12="","",F12) | G44: =IF(G12="","",G12) | H44: =IF(H12="","",H12) | I44: =IFERROR(SUM(F44*H44),"") | J44: 3 | K44: 4
A45: 4 | B45: =IF(B13="","",B13) | D45: =IF(D13="","",D13) | E45: =IF(E13="","",E13) | F45: =IF(F13="","",F13) | G45: =IF(G13="","",G13) | H45: =IF(H13="","",H13) | I45: =IFERROR(SUM(F45*H45),"")
A46: JUMLAH | I46: =SUM(I42:I45) -> 450000
J48: =Transpor_bank!J48 -> Cikalongwetan, 4 Februari 2026
C49: Mengetahui/Menyetujui | J49: =Transpor_bank!J49 -> Dibayar Lunas Tgl. 4 Februari 2026
C50: Kepala Sekolah, | J50: Bendahara BOS,
C56: =C24 -> BADRUDDIN, S.Ag. | J56: =J24 -> DEDE GUNAWAN, S.Pd.
C57: =C25 -> NIP. 197405082014121002 | J57: =J25 -> NIP. 198507172020121003
A65: =$A$1 -> DAFTAR BUKTI PENERIMA PERJALANAN DINAS KOORDINASI PENGELOLAAN DANA BOSP (Transaksi Non Tunai)
A66: =Transpor_bank!A66 -> BULAN MARET 2026
C68: Nomor | D68: : _____________________________ | I68: Program | J68: =J36 -> : 06 Pengembangan Standar Pengelolaan
C69: Nama Sekolah | D69: =D37 -> : SD NEGERI LEBAKLEUNGSIR | I69: Kegiatan | J69: =J37 -> : Perjalanan Dinas koordinasi
C70: Kecamatan | D70: =D38 -> : Cikalongwetan | I70: Kode Rekening | J70: =J38 -> : 5.1.02.04.01.0003
C71: Kabupaten | D71: =D39 -> : Bandung Barat | I71: Kode Penggunaan | J71: =J39 -> : 5
...

Sheet Transpor_rapat
A1: DAFTAR BUKTI PENERIMA PERJALANAN DINAS RAPAT KERJA TEKNIS OPERATOR TK. GUGUS (Transaksi Non Tunai)
A2: =Transpor_koordinasi!A2 -> BULAN JANUARI 2026
C4: Nomor | D4: =Transpor_koordinasi!D4 -> : ____________________________ | I4: Program | J4: : 06 Pengembangan Standar Pengelolaan
C5: Nama Sekolah | D5: =Transpor_koordinasi!D5 -> : SD NEGERI LEBAKLEUNGSIR | I5: Kegiatan | J5: : Perjalanan Dinas Rakernis Operator
C6: Kecamatan | D6: =Transpor_koordinasi!D6 -> : Cikalongwetan | I6: Kode Rekening | J6: : 5.1.02.04.01.0003
C7: Kabupaten | D7: =Transpor_koordinasi!D7 -> : Bandung Barat | I7: Kode Penggunaan | J7: : 5
A9: NO | B9: NAMA PTK | D9: JABATAN | E9: Gol. / Ruang | F9: VOL | G9: SATUAN | H9: UNIT COST (Rp) | I9: JUMLAH (Rp) | J9: TANDA TANGAN
A10: 1 | B10: RISNA MARSELA HARTINI | D10: Operator | E10: - | F10: 2 | G10: Perjalanan | H10: 75000 | I10: =F10*H10 -> 150000 | J10: 1 | K10: 2
A11: 2 | I11: =F11*H11 -> 0
A12: 3 | I12: =F12*H12 -> 0 | J12: 3 | K12: 4
A13: 4 | I13: =F13*H13 -> 0
A14: JUMLAH | I14: =SUM(I10:I13) -> 150000
J16: Cikalongwetan, 23 Januari 2025
C17: Mengetahui/Menyetujui | J17: =Honor_penjaga!O20 -> Dibayar Lunas Tgl. 4 Februari 2026
C18: Kepala Sekolah, | J18: Bendahara BOS,
C24: =Transpor_koordinasi!C24 -> BADRUDDIN, S.Ag. | J24: =Transpor_koordinasi!J24 -> DEDE GUNAWAN, S.Pd.
C25: =Transpor_koordinasi!C25 -> NIP. 197405082014121002 | J25: =Transpor_koordinasi!J25 -> NIP. 198507172020121003
A33: =$A$1 -> DAFTAR BUKTI PENERIMA PERJALANAN DINAS RAPAT KERJA TEKNIS OPERATOR TK. GUGUS (Transaksi Non Tunai)
A34: =Transpor_koordinasi!A34 -> BULAN FEBRUARI 2026
C36: Nomor | D36: : _____________________________ | I36: Program | J36: =J4 -> : 06 Pengembangan Standar Pengelolaan
C37: Nama Sekolah | D37: =D5 -> : SD NEGERI LEBAKLEUNGSIR | I37: Kegiatan | J37: =J5 -> : Perjalanan Dinas Rakernis Operator
C38: Kecamatan | D38: =D6 -> : Cikalongwetan | I38: Kode Rekening | J38: =J6 -> : 5.1.02.04.01.0003
C39: Kabupaten | D39: =D7 -> : Bandung Barat | I39: Kode Penggunaan | J39: =J7 -> : 5
A41: NO | B41: NAMA PTK | D41: JABATAN | E41: Gol. / Ruang | F41: VOL | G41: SATUAN | H41: UNIT COST (Rp) | I41: JUMLAH (Rp) | J41: TANDA TANGAN
A42: 1 | B42: =IF(B10="","",B10) -> RISNA MARSELA HARTINI | D42: =IF(D10="","",D10) -> Operator | E42: =IF(E10="","",E10) -> - | F42: 4 | G42: =IF(G10="","",G10) -> Perjalanan | H42: 50000 | I42: =IFERROR(SUM(F42*H42),"") -> 200000 | J42: 1 | K42: 2
A43: 2 | B43: =IF(B11="","",B11) | D43: =IF(D11="","",D11) | E43: =IF(E11="","",E11) | F43: =IF(F11="","",F11) | G43: =IF(G11="","",G11) | H43: =IF(H11="","",H11) | I43: =IFERROR(SUM(F43*H43),"")
A44: 3 | B44: =IF(B12="","",B12) | D44: =IF(D12="","",D12) | E44: =IF(E12="","",E12) | F44: =IF(F12="","",F12) | G44: =IF(G12="","",G12) | H44: =IF(H12="","",H12) | I44: =IFERROR(SUM(F44*H44),"") | J44: 3 | K44: 4
A45: 4 | B45: =IF(B13="","",B13) | D45: =IF(D13="","",D13) | E45: =IF(E13="","",E13) | F45: =IF(F13="","",F13) | G45: =IF(G13="","",G13) | H45: =IF(H13="","",H13) | I45: =IFERROR(SUM(F45*H45),"")
A46: JUMLAH | I46: =SUM(I42:I45) -> 200000
J48: =Transpor_koordinasi!J48 -> Cikalongwetan, 4 Februari 2026
C49: Mengetahui/Menyetujui | J49: =Transpor_koordinasi!J49 -> Dibayar Lunas Tgl. 4 Februari 2026
C50: Kepala Sekolah, | J50: Bendahara BOS,
C56: =C24 -> BADRUDDIN, S.Ag. | J56: =J24 -> DEDE GUNAWAN, S.Pd.
C57: =C25 -> NIP. 197405082014121002 | J57: =J25 -> NIP. 198507172020121003
A65: =$A$1 -> DAFTAR BUKTI PENERIMA PERJALANAN DINAS RAPAT KERJA TEKNIS OPERATOR TK. GUGUS (Transaksi Non Tunai)
A66: =Transpor_koordinasi!A66 -> BULAN MARET 2026
C68: Nomor | D68: : _____________________________ | I68: Program | J68: =J36 -> : 06 Pengembangan Standar Pengelolaan
C69: Nama Sekolah | D69: =D37 -> : SD NEGERI LEBAKLEUNGSIR | I69: Kegiatan | J69: =J37 -> : Perjalanan Dinas Rakernis Operator
C70: Kecamatan | D70: =D38 -> : Cikalongwetan | I70: Kode Rekening | J70: =J38 -> : 5.1.02.04.01.0003
C71: Kabupaten | D71: =D39 -> : Bandung Barat | I71: Kode Penggunaan | J71: =J39 -> : 5
...

Sheet Transpor_pendamping
A1: DAFTAR BUKTI PENERIMA PERJALANAN DINAS PENDAMPING PESERTA TKA (Transaksi Non Tunai)
A2: BULAN APRIL 2026
C4: Nomor | D4: =Transpor_rapat!D4 -> : ____________________________ | I4: Program | J4: : 08 Standar Penilaian
C5: Nama Sekolah | D5: =Transpor_rapat!D5 -> : SD NEGERI LEBAKLEUNGSIR | I5: Kegiatan | J5: : Perjalanan Dinas Pendamping TKA
C6: Kecamatan | D6: =Transpor_rapat!D6 -> : Cikalongwetan | I6: Kode Rekening | J6: : 5.1.02.04.01.0003
C7: Kabupaten | D7: =Transpor_rapat!D7 -> : Bandung Barat | I7: Kode Penggunaan | J7: : 5
A9: NO | B9: NAMA PTK | D9: JABATAN | E9: Gol. / Ruang | F9: VOL | G9: SATUAN | H9: UNIT COST (Rp) | I9: JUMLAH (Rp) | J9: TANDA TANGAN
A10: 1 | B10: DEDE GUNAWAN | D10: Guru Kelas | E10: III/b | F10: 2 | G10: Perjalanan | H10: 75000 | I10: =F10*H10 -> 150000 | J10: 1 | K10: 2
A11: 2 | E11: - | I11: =F11*H11 -> 0
A12: 3 | I12: =F12*H12 -> 0 | J12: 3 | K12: 4
A13: 4 | I13: =F13*H13 -> 0
A14: JUMLAH | I14: =SUM(I10:I13) -> 150000
J16: Cikalongwetan, 7 April 2026
C17: Mengetahui/Menyetujui | J17: Dibayar Lunas Tgl. 7 April 2026
C18: Kepala Sekolah, | J18: Bendahara BOS,
C24: =Transpor_rapat!C253 -> BADRUDDIN, S.Ag. | J24: =Honor_penjaga!O423 -> DEDE GUNAWAN, S.Pd
C25: =Transpor_rapat!C254 -> NIP. 197405082014121002 | J25: =Honor_penjaga!O424 -> NIP. 198507172020121003

Sheet Upah
A1: DAFTAR BUKTI PENERIMA JASA/UPAH KERJA PEMELIHARAAN HALAMAN SEKOLAH
C4: Nomor | D4: : _____________________________ | K4: Program | L4: : 05 Pengembangan Standar Sarpras
C5: Nama Sekolah | D5: =Honor_guru!D5 -> : SD NEGERI LEBAKLEUNGSIR | K5: Kegiatan | L5: : Upah Kerja Pemeliharaan
C6: Kecamatan | D6: : Cikalongwetan | K6: Kode Rekening | L6: : 5.1.02.02.01.0016
C7: Kabupaten | D7: : Bandung Barat | K7: Kode Penggunaan | L7: : 8
A9: NO | B9: NAMA PTK | D9: JABATAN | E9: Gol. / Ruang | F9: VOLUME | H9: UNIT COST (Rp) | I9: JUMLAH (Rp) | J9: PPh 21 | K9: JUMLAH YANG DITERIMA (Rp) | L9: TANDA TANGAN
A10: 1 | B10: IMAN | D10: Pekerja/Tukang | E10: - | F10: 3 | G10: Hari | H10: 125000 | I10: =SUM(F10*H10) -> 375000 | J10: =I10*0/100 -> 0 | K10: =SUM(I10-J10) -> 375000 | L10: 1 | M10: 2
A11: 2 | I11: =SUM(F11*H11) -> 0 | J11: =I11*5/100 -> 0 | K11: =SUM(I11-J11) -> 0
A12: 3 | I12: =SUM(F12*H12) -> 0 | J12: =I12*5/100 -> 0 | K12: =SUM(I12-J12) -> 0 | L12: 3 | M12: 4
A13: 4 | I13: =SUM(F13*H13) -> 0 | J13: =I13*0/100 -> 0 | K13: =SUM(I13-J13) -> 0
A14: JUMLAH | I14: =SUM(I10:I13) -> 375000 | J14: =SUM(J10:J13) -> 0 | K14: =SUM(K10:K13) -> 375000
L16: ..
C17: Mengetahui/Menyetujui | L17: ..
C18: Kepala Sekolah, | L18: Bendahara BOS,
C24: =Honor_guru!C27 -> BADRUDDIN, S.Ag. | L24: =Honor_guru!P27 -> DEDE GUNAWAN, S.Pd.
C25: =Honor_guru!C28 -> NIP. 197405082014121002 | L25: =Honor_guru!P28 -> NIP. 198507172020121003

Sheet Pulsa
A1: DAFTAR PENERIMA KUOTA/PULSA INTERNET OPERATOR
A2: =Transpor_rapat!A2 -> BULAN JANUARI 2026
C4: Nomor | D4: =Transpor_pendamping!D4 -> : ____________________________ | I4: Program | J4: : 06 Pengembangan Standar Pengelolaan
C5: Nama Sekolah | D5: =Transpor_pendamping!D5 -> : SD NEGERI LEBAKLEUNGSIR | I5: Kegiatan | J5: : Pengisian Pulsa Internet
C6: Kecamatan | D6: =Transpor_pendamping!D6 -> : Cikalongwetan | I6: Kode Rekening | J6: : 5.1.02.02.01.0063
C7: Kabupaten | D7: =Transpor_pendamping!D7 -> : Bandung Barat | I7: Kode Penggunaan | J7: : 7
A9: NO | B9: NAMA PTK | D9: JABATAN | E9: NOMOR HP | F9: VOL | G9: SATUAN | H9: UNIT COST (Rp) | I9: JUMLAH (Rp) | J9: TANDA TANGAN
A10: 1 | B10: RISNA MARSELA HARTINI | D10: Operator | E10: +62 882-2908-8313 | F10: 1 | G10: Paket | H10: 105000 | I10: =F10*H10 -> 105000 | J10: 1 | K10: 2
A11: 2 | I11: =F11*H11 -> 0
A12: 3 | I12: =F12*H12 -> 0 | J12: 3 | K12: 4
A13: 4 | I13: =F13*H13 -> 0
A14: 5 | I14: =F14*H14 -> 0 | J14: 5 | K14: 6
A15: 6 | I15: =F15*H15 -> 0
A16: 7 | I16: =F16*H16 -> 0 | J16: 7 | K16: 8
A17: 8 | I17: =F17*H17 -> 0
A18: JUMLAH | I18: =SUM(I10:I17) -> 105000
J20: =Transpor_rapat!J16 -> Cikalongwetan, 23 Januari 2025
C21: Mengetahui/Menyetujui | J21: =Transpor_rapat!J17 -> Dibayar Lunas Tgl. 4 Februari 2026
C22: Kepala Sekolah, | J22: Bendahara BOS,
C27: =Honor_guru!C27 -> BADRUDDIN, S.Ag. | J27: =Honor_guru!P27 -> DEDE GUNAWAN, S.Pd.
C28: =Honor_guru!C28 -> NIP. 197405082014121002 | J28: =Honor_guru!P28 -> NIP. 198507172020121003
A43: =A1 -> DAFTAR PENERIMA KUOTA/PULSA INTERNET OPERATOR
A44: =Transpor_rapat!A34 -> BULAN FEBRUARI 2026
C46: Nomor | D46: =D4 -> : ____________________________ | I46: Program | J46: =J4 -> : 06 Pengembangan Standar Pengelolaan
C47: Nama Sekolah | D47: =D5 -> : SD NEGERI LEBAKLEUNGSIR | I47: Kegiatan | J47: =J5 -> : Pengisian Pulsa Internet
C48: Kecamatan | D48: =D6 -> : Cikalongwetan | I48: Kode Rekening | J48: =J6 -> : 5.1.02.02.01.0063
C49: Kabupaten | D49: =D7 -> : Bandung Barat | I49: Kode Penggunaan | J49: =J7 -> : 7
A51: NO | B51: NAMA PTK | D51: JABATAN | E51: NOMOR HP | F51: VOL | G51: SATUAN | H51: UNIT COST (Rp) | I51: JUMLAH (Rp) | J51: TANDA TANGAN
A52: 1 | B52: =B10 -> RISNA MARSELA HARTINI | D52: =D10 -> Operator | E52: =E10 -> +62 882-2908-8313 | F52: 1 | G52: Paket | H52: 105000 | I52: =F52*H52 -> 105000 | J52: 1 | K52: 2
A53: 2 | I53: =F53*H53 -> 0
A54: JUMLAH | I54: =SUM(I52:I53) -> 105000
J56: =Transpor_rapat!J48 -> Cikalongwetan, 4 Februari 2026
C57: Mengetahui/Menyetujui | J57: =Transpor_rapat!J49 -> Dibayar Lunas Tgl. 4 Februari 2026
C58: Kepala Sekolah, | J58: Bendahara BOS,
C63: =C27 -> BADRUDDIN, S.Ag. | J63: =J27 -> DEDE GUNAWAN, S.Pd.
C64: =C28 -> NIP. 197405082014121002 | J64: =J28 -> NIP. 198507172020121003
A79: =A43 -> DAFTAR PENERIMA KUOTA/PULSA INTERNET OPERATOR
A80: =Transpor_rapat!A66 -> BULAN MARET 2026
C82: Nomor | D82: =D46 -> : ____________________________ | I82: Program | J82: =J46 -> : 06 Pengembangan Standar Pengelolaan
C83: Nama Sekolah | D83: =D47 -> : SD NEGERI LEBAKLEUNGSIR | I83: Kegiatan | J83: =J47 -> : Pengisian Pulsa Internet
...
