Workbook
Name bulan: '[1]F-1_Reg'!$R$6:$R$17
Name jabatan: '[1]Data Sekolah'!$X$4:$X$11
Name jenis_setoran: [2]Januari!$S$2:$S$5
Name kap: [2]Januari!$R$2:$R$5
Name pangkat: '[1]Data Sekolah'!$V$4:$V$12
Name pendidikan: '[1]Data Sekolah'!$W$4:$W$12

Sheet Data
A3: Nama Kepala Sekolah | B3: : | C3: YUNIARTI, S.Pd
A4: NIP | B4: : | C4: 196607071986102005
A5: No. SK. Kepala Sekolah | B5: : | C5: 821.2/Kep.391-BKD/2014
A6: Tanggal | B6: : | C6: 41873
A8: Nama Bendahara | B8: : | C8: AHMAD, S.Pd
A9: NIP | B9: : | C9: 196805251992121003
A10: No. SK. Bendahara | B10: : | C10: 400.3.5.5/083/SDNPSR/2024
A11: Tanggal | B11: : | C11: 45605
A13: No. SK | B13: : | C13: 100.3.3.2/Kep.77-BKAD/2025
A14: Tanggal | B14: : | C14: 45707

Sheet BKU--
A1: Uraian | B1: Penerimaan | C1: Pengeluaran | D1: Saldo Akhir Buku Kas Umum | E1: Saldo BKU Akhir Kas Tunai | F1: Saldo BKU Akhir Bank | G1: Pajak
A3: Saldo 2024 | E3: 0 | F3: 0
A4: Januari | B4: =BKU!C21+BKU!E4 -> 82560000 | C4: =BKU!D30 -> 0 | D4: =BKU!D29 -> 82560000 | E4: =BKU!D28 -> 0 | F4: =BKU!D27 -> 82560000 | G4: =BKU!D32 -> 0 | H4: =B4-C4-D4 -> 0
A5: Februari | B5: =BKU!D57 -> 82560000 | C5: =BKU!D64 -> 26100000 | D5: =B5-C5 -> 56460000 | E5: =BKU!D62 -> 7990000 | F5: =BKU!D61 -> 48470000 | G5: =BKU!D66 -> 168000 | H5: =B5-C5-D5 -> 0
A6: Maret | B6: =BKU!D91 -> 56460000 | C6: =BKU!D98 -> 1650000 | D6: =B6-C6 -> 54810000 | E6: =BKU!D96 -> 6340000 | F6: =BKU!D95 -> 48470000 | G6: =BKU!D100 -> 96000 | H6: =B6-C6-D6 -> 0
A7: April | B7: =BKU!D125 -> 54810000 | C7: =BKU!D132 -> 33810000 | D7: =B7-C7 -> 21000000 | E7: =BKU!D130 -> 3570000 | F7: =BKU!D129 -> 17430000 | G7: =BKU!D134 -> 168000 | H7: =B7-C7-D7 -> 0
A8: Mei | B8: =BKU!D159 -> 21000000 | C8: =BKU!D166 -> 1650000 | D8: =B8-C8 -> 19350000 | E8: =BKU!D164 -> 1920000 | F8: =BKU!D163 -> 17430000 | G8: =BKU!D168 -> 24000 | H8: =B8-C8-D8 -> 0
A9: Juni | B9: =BKU!D193 -> 19350000 | C9: =BKU!D200 -> 19350000 | D9: =B9-C9 -> 0 | E9: =BKU!D198 -> 0 | F9: =BKU!D197 -> 0 | G9: =BKU!D202 -> 210000 | H9: =B9-C9-D9 -> 0
A10: Juli | B10: =BKU!D227 -> 0 | C10: =BKU!D234 -> 0 | D10: =B10-C10 -> 0 | E10: =BKU!D232 -> 0 | F10: =BKU!D231 -> 0 | G10: =BKU!D236 -> 0 | H10: =B10-C10-D10 -> 0
A11: Agustus | B11: =BKU!D261 -> 82560000 | C11: =BKU!D268 -> 47710000 | D11: =B11-C11 -> 34850000 | E11: =BKU!D266 -> 14040000 | F11: =BKU!D265 -> 20810000 | G11: =BKU!D270 -> 0 | H11: =B11-C11-D11 -> 0
A12: September | B12: =BKU!D295 -> 34850000 | C12: =BKU!D302 -> 5650000 | D12: =B12-C12 -> 29200000 | E12: =BKU!D300 -> 8390000 | F12: =BKU!D299 -> 20810000 | G12: =BKU!D304 -> 208000 | H12: =B12-C12-D12 -> 0
A13: Oktober | B13: =BKU!D329 -> 29200000 | C13: =BKU!D336 -> 12300000 | D13: =B13-C13 -> 16900000 | E13: =BKU!D334 -> 1490000 | F13: =BKU!D333 -> 15410000 | G13: =BKU!D338 -> 246000 | H13: =B13-C13-D13 -> 0
A14: November | B14: =BKU!D363 -> 16900000 | C14: =BKU!D370 -> 1490000 | D14: =B14-C14 -> 15410000 | E14: =BKU!D368 -> 0 | F14: =BKU!D367 -> 15410000 | G14: =BKU!D372 -> 24000 | H14: =B14-C14-D14 -> 0
A15: Desember | B15: =BKU!D397 -> 15410000 | C15: =BKU!D404 -> 15410000 | D15: =B15-C15 -> 0 | E15: =BKU!D402 -> 0 | F15: =BKU!D401 -> 0 | G15: =BKU!D406 -> 166000 | H15: =B15-C15-D15 -> 0
B16: =SUM(B5:B11) -> 316740000 | C16: =SUM(C5:C11) -> 130270000

Sheet BKU
B1: Uraian | C1: Penarimaan | D1: Pengeluaran | E1: Saldo
B2: Belanja Januari 2025
B3: Saldo Bank Bulan Desember 2024 | C3: 0 | E3: =C3 -> 0
B4: Saldo Tunai Bulan Desember 2024 | C4: 0 | E4: =E3+C4-D4 -> 0
B5: PENERIMAAN TAHAP 1 | C5: 82560000 | E5: =E4+C5-D5 -> 82560000
B6: Tarik Tunai | E6: =E5+C6-D6 -> 82560000
B7: Tarik Tunai | E7: =E6+C7-D7 -> 82560000
B8: Tarik Tunai | E8: =E7+C8-D8 -> 82560000
B9: BELANJA BPU | E9: =E8+C9-D9 -> 82560000
B10: BELANJA BNU | E10: =E9+C10-D10 -> 82560000
B11: TERIMA PAJAK | E11: =E10+C11-D11 -> 82560000
B12: SETOR PAJAK | E12: =E11+C12-D12 -> 82560000
E13: =E12+C13-D13 -> 82560000
E14: =E13+C14-D14 -> 82560000
E15: =E14+C15-D15 -> 82560000
E16: =E15+C16-D16 -> 82560000
E17: =E16+C17-D17 -> 82560000
E18: =E17+C18-D18 -> 82560000
E19: =E18+C19-D19 -> 82560000
E20: =E19+C20-D20 -> 82560000
B21: JUMLAH | C21: =C5 -> 82560000 | D21: =SUM(D6:D10) -> 0 | E21: =C21-D21 -> 82560000
B23: PENERIMAAN TAHAP 1 | D23: =SUMIF(B5:B20,"PENERIMAAN TAHAP 1",C5:C20) -> 82560000
B24: BELANJA BNU | D24: =SUMIF(B6:B20,"BELANJA BNU",D6:D20) -> 0
B25: BELANJA BPU | D25: =SUMIF(B6:B20,"BELANJA BPU",D6:D20) -> 0
B26: TARIK TUNAI | D26: =SUMIF(B5:B20,"TARIK TUNAI",D5:D20) -> 0
B27: SALDO BANK | D27: =D23-D26-D24 -> 82560000
B28: SALDO KAS | D28: =MAX(0,D26-D25) -> 0
B29: SALDO KAS UMUM | D29: =D27+D28 -> 82560000
B30: PENGELUARAN BKU | D30: =D24+D25 -> 0
B31: TERIMA PAJAK | D31: =SUMIF(B5:B20,"TERIMA PAJAK",C5:C20) -> 0
B32: SETOR PAJAK | D32: =SUMIF(B5:B20,"SETOR PAJAK",D5:D20) -> 0
B35: Uraian | C35: Penarimaan | D35: Pengeluaran | E35: Saldo
B36: Belanja Februari 2025
B37: Saldo Bank Bulan Januari 2025 | C37: =D27 -> 82560000 | E37: =C37 -> 82560000
B38: Saldo Tunai Bulan Januari 2025 | C38: =D28 -> 0 | E38: =E37+C38-D38 -> 82560000
E39: =E38+C39-D39 -> 82560000
B40: Tarik Tunai | D40: 12410000 | E40: =E39+C40-D40 -> 70150000
B41: Tarik Tunai | E41: =E40+C41-D41 -> 70150000
B42: Tarik Tunai | E42: =E41+C42-D42 -> 70150000
B43: BELANJA BPU | D43: 4420000 | E43: =E42+C43-D43 -> 65730000
...

Sheet Register_Kas
K2: Pilih
B3: REGISTER PENUTUPAN KAS | K3: Desember
B4: BOS REGULER
B5: =UPPER("PERIODE : BULAN "&VLOOKUP($K$3,$L$15:$N$27,1,FALSE)&" 2025") -> PERIODE : BULAN DESEMBER 2025
B7: Tanggal Penutupan Kas | E7: : | F7: =VLOOKUP($K$3,$L$15:$N$27,3,FALSE) -> 46022
B8: Nama Penutup Kas (Pemegang kas) | E8: : | F8: =Data!C8 -> AHMAD, S.Pd
B9: Tanggal penutupan Kas yang lalu | E9: : | F9: =VLOOKUP($K$3,$L$15:$N$27,2,FALSE) -> 45990
B10: Jumlah Total Penerimaan (D) | E10: : | F10: =VLOOKUP($K$3,'BKU--'!$A$1:$G$15,2,FALSE) -> 15410000
B11: Jumlah Total Pengeluaran (K) | E11: : | F11: =VLOOKUP($K$3,'BKU--'!$A$1:$G$15,3,FALSE) -> 15410000
B12: Saldo Buku (A = D - K) | E12: : | F12: =F10-F11 -> 0
B13: Saldo Kas ( B ) | E13: : | F13: =H23+H29+H31 -> 0
C15: Sado Kas B terdiri dari : | K15: Saldo Kas | L15: Bulan | M15: Tanggal Penutupan Kas | N15: Tanggal penutupan Kas yang lalu | P15: 100000 | Q15: 50000 | R15: 20000 | S15: 10000 | T15: 5000 | U15: 2000 | V15: 1000 | W15: 500 | X15: 200 | Y15: 100
B16: 1. | C16: Lembaran uang kertas | D16: 100000 | E16: =H16/D16 -> 0 | G16: Lembar | H16: =P16 -> 0 | K16: =VLOOKUP($K$3,'BKU--'!$A$1:$G$15,5,FALSE) -> 0 | L16: Januari | M16: 45657 | N16: 45688 | O16: =K16 -> 0 | P16: =FLOOR($O16,P$15) -> 0 | Q16: =FLOOR($O16-P16,Q$15) -> 0 | R16: =FLOOR($O16-SUM($P16:Q16),R$15) -> 0 | S16: =FLOOR($O16-SUM($P16:R16),S$15) -> 0 | T16: =FLOOR($O16-SUM($P16:S16),T$15) -> 0 | U16: =FLOOR($O16-SUM($P16:T16),U$15) -> 0 | V16: =FLOOR($O16-SUM($P16:U16),V$15) -> 0 | W16: =FLOOR($O16-SUM($P16:V16),W$15) -> 0 | X16: =FLOOR($O16-SUM($P16:W16),X$15) -> 0 | Y16: =FLOOR($O16-SUM($P16:X16),Y$15) -> 0
C17: Lembaran uang kertas | D17: 50000 | E17: =H17/D17 -> 0 | G17: Lembar | H17: =Q16 -> 0 | L17: Februari | M17: 45688 | N17: 45716
C18: Lembaran uang kertas | D18: 20000 | E18: =H18/D18 -> 0 | G18: Lembar | H18: =R16 -> 0 | L18: Maret | M18: 45716 | N18: 45743
C19: Lembaran uang kertas | D19: 10000 | E19: =H19/D19 -> 0 | G19: Lembar | H19: =S16 -> 0 | L19: April | M19: 45743 | N19: 45777
C20: Lembaran uang kertas | D20: 5000 | E20: =H20/D20 -> 0 | G20: Lembar | H20: =T16 -> 0 | L20: Mei | M20: 45777 | N20: 45808
C21: Lembaran uang kertas | D21: 2000 | E21: =H21/D21 -> 0 | G21: Lembar | H21: =U16 -> 0 | L21: Juni | M21: 45808 | N21: 45838
C22: Lembaran uang kertas | D22: 1000 | E22: =H22/D22 -> 0 | G22: Lembar | H22: =V16 -> 0 | L22: Juli | M22: 45838 | N22: 45869
F23: Sub Jumlah (1) | H23: =SUM(H16:H22) -> 0 | L23: Agustus | M23: 45869 | N23: 45899
L24: September | M24: 45899 | N24: 45930
B25: 2. | C25: Keping uang logam | D25: 1000 | E25: 0 | G25: Keping | H25: =D25*E25 -> 0 | L25: Oktober | M25: 45930 | N25: 45961
C26: Keping uang logam | D26: 500 | E26: =H26/D26 -> 0 | G26: Keping | H26: =W16 -> 0 | L26: November | M26: 45961 | N26: 45990
C27: Keping uang logam | D27: 200 | E27: =H27/D27 -> 0 | G27: Keping | H27: =X16 -> 0 | L27: Desember | M27: 45990 | N27: 46022
C28: Keping uang logam | D28: 100 | E28: =H28/D28 -> 0 | G28: Keping | H28: =Y16 -> 0
F29: Sub Jumlah (2) | H29: =SUM(H25:H28) -> 0
B31: 3. | C31: Saldo Bank, Surat Berharga, dll. | F31: Sub Jumlah (3) | H31: =VLOOKUP($K$3,'BKU--'!$A$1:$G$15,6,FALSE) -> 0
F33: Jumlah ( 1 + 2 + 3 ) | H33: =H23+H29+H31 -> 0
C35: Perbedaan (A - B) | H35: =F12-F13 -> 0
C37: Penjelasan Perbedaan | D37: =": disebabkan tidak ada pecahan uang - "&H3&" pada saat transaksi." -> : disebabkan tidak ada pecahan uang - pada saat transaksi.
H39: ="Tanggal : "&TEXT(VLOOKUP($K$3,$L$15:$N$27,3,FALSE),"dd mmmm yyyy") -> Tanggal : 31 December 2025
C40: Yang diperiksa, | H40: Yang memeriksa
C41: Bendahara/Pemegang Kas, | H41: Kepala Sekolah,
C47: =Data!C8 -> AHMAD, S.Pd | H47: =Data!C3 -> YUNIARTI, S.Pd
C48: ="NIP. "&Data!C9 -> NIP. 196805251992121003 | H48: ="NIP. "&Data!C4 -> NIP. 196607071986102005

Sheet BA_Kas
B2: BERITA ACARA PEMERIKSAAN KAS | H2: Pilih
B3: =UPPER("PERIODE : BULAN "&VLOOKUP($H$3,$I$15:$K$27,1,FALSE)&" 2025") -> PERIODE : BULAN DESEMBER 2025 | H3: Desember
B5: ="Pada hari ini "&VLOOKUP($H$3,$I$16:$N$27,4,FALSE)&" tanggal "&VLOOKUP($H$3,$I$16:$N$27,3,FALSE)&" bulan "&VLOOKUP($H$3,$I$16:$N$27,1,FALSE)&" tahun Dua ribu dua puluh lima. Yang bertanda tangan di bawah ini, kami Kepala Sekolah yang ditunjuk berdasarkan Surat Keputusan Nomor: "&Data!C5&" tanggal "&TEXT(Data!C6,"dd mmmm yyyy") -> Pada hari ini Rabu tanggal tiga puluh satu bulan Desember tahun Dua ribu dua puluh lima. Yang bertanda tangan di bawah ini, kami Kepala Sekolah yang ditunjuk berdasarkan Surat Keputusan Nomor: 821.2/Kep.391-BKD/2014 tanggal 22 August 2014
C8: Nama | D8: =": "&Data!C3 -> : YUNIARTI, S.Pd
C9: Jabatan | D9: : Kepala Sekolah
B11: melakukan pemeriksaan kas kepada:
C13: Nama | D13: =": "&Data!C8 -> : AHMAD, S.Pd
C14: Jabatan | D14: : Bendahara
I15: Bulan
B16: ="Yang berdasarkan Surat Keputusan Bupati Bandung Barat Nomor : "&Data!C13&" tanggal "&TEXT(Data!C14,"dd mmmm yyyy")&" dan Surat Keputusan Kepala Sekolah Nomor : "&Data!C10&" tanggal "&TEXT(Data!C11,"dd mmmm yyyy")&" ditunjuk sebagai Bendahara Bantuan Operasional Sekolah Tingkat Sekolah Dasar Tahun Anggaran 2025." -> Yang berdasarkan Surat Keputusan Bupati Bandung Barat Nomor : 100.3.3.2/Kep.77-BKAD/2025 tanggal 19 February 2025 dan Surat Keputusan Kepala Sekolah Nomor : 400.3.5.5/083/SDNPSR/2024 tanggal 09 November 2024 ditunjuk sebagai Bendahara Bantuan Operasional Sekolah Tingkat Sekolah Dasar Tahun Anggaran 2025. | I16: Januari | J16: 45688 | K16: tiga puluh satu | L16: Jumat
I17: Februari | J17: 45716 | K17: dua puluh delapan | L17: Jumat
I18: Maret | J18: 45743 | K18: dua puluh tujuh | L18: Kamis
B19: Berdasarkan pemeriksaan kas serta bukti-bukti dalam pengurusan itu, kami menemui kenyataan sebagai berikut: | I19: April | J19: 45777 | K19: tiga puluh | L19: Rabu
I20: Mei | J20: 45808 | K20: tiga puluh satu | L20: Sabtu
B21: Jumlah uang yang dihitung dihadapan Bendahara/Pemegang Kas adalah : | I21: Juni | J21: 45838 | K21: tiga puluh | L21: Senin
B22: a) | C22: Uang kertas bank, uang logam | E22: =VLOOKUP($H$3,'BKU--'!$A$1:$G$15,5,FALSE) -> 0 | I22: Juli | J22: 45869 | K22: tiga puluh satu | L22: Kamis
B23: b) | C23: Saldo Bank | E23: =VLOOKUP($H$3,'BKU--'!$A$1:$G$15,6,FALSE) -> 0 | I23: Agustus | J23: 45899 | K23: tiga puluh | L23: Sabtu
B24: c) | C24: Surat berharga, dll. | E24: 0 | I24: September | J24: 45930 | K24: tiga puluh | L24: Selasa
D25: Jumlah | E25: =SUM(E22:E24) -> 0 | I25: Oktober | J25: 45961 | K25: tiga puluh satu | L25: Jumat
I26: November | J26: 45990 | K26: dua puluh sembilan | L26: Sabtu
B27: Saldo uang menurut Kas Umum | E27: =VLOOKUP($H$3,'BKU--'!$A$1:$G$15,4,FALSE) -> 0 | I27: Desember | J27: 46022 | K27: tiga puluh satu | L27: Rabu
B28: Perbedaan antara saldo Kas dan saldo Buku | E28: =VLOOKUP($H$3,'BKU--'!$A$1:$H$15,8,FALSE) -> 0
E30: ="Tanggal : "&TEXT(VLOOKUP($H$3,$I$16:$K$27,2,FALSE),"dd mmmm yyyy") -> Tanggal : 31 December 2025
C31: Bendahara/Pemegang Kas, | E31: Kepala Sekolah,
C36: =Register_Kas!C47 -> AHMAD, S.Pd | E36: =Register_Kas!H47 -> YUNIARTI, S.Pd
C37: =Register_Kas!C48 -> NIP. 196805251992121003 | E37: =Register_Kas!H48 -> NIP. 196607071986102005
